Workbook
Name Saldo_Ago24: #REF!
Name Saldo_Jul24: #REF!
Name Saldo_Jun24: #REF!
Name Saldo_nov24: #REF!
Name SAldo_out24: #REF!
Name Saldo_Set24: #REF!

Sheet Jan.25
A1: 1 | B1: 1 | C1: 1 | D1: 1 | E1: 1 | F1: 1 | G1: 1 | H1: 1 | I1: 1 | J1: 1 | K1: 1 | L1: 1 | M1: 1 | N1: 1 | O1: 1 | P1: 1
C3: Bluzz Saúde Ltda.
A4: 1 | C4: CNPJ | D4: 54.557.861/0001-02 | P4: 1
A5: 1 | C5: Colaborador | P5: 1
A6: 1 | C6: Mês Competência | D6: 45658 | P6: 1
A7: 1 | P7: 1
A8: 1 | C8: Saldo final em 31/12/2025 | E8: em horas | P8: 1
A9: 1 | P9: 1
A10: 1 | C10: CONTROLE DE PONTO | P10: 1
A11: 1 | C11: Data | D11: Dia da semana | E11: Entrada | F11: Saída Almoço | G11: Retorno Almoço | H11: Saída | I11: Horas Trabalhadas | J11: Horas Normais | K11: Horas Extras | L11: Banco de Horas | P11: 1
A12: 1 | C12: 45658 | D12: =CHOOSE(WEEKDAY(C12,2),'Não Apagar'!$C$3,'Não Apagar'!$C$4,'Não Apagar'!$C$5,'Não Apagar'!$C$6,'Não Apagar'!$C$7,'Não Apagar'!$C$8,'Não Apagar'!$C$9) -> Quarta-feira | H12: Feriado | P12: 1
A13: 1 | C13: =C12+1 -> 45659 | D13: =CHOOSE(WEEKDAY(C13,2),'Não Apagar'!$C$3,'Não Apagar'!$C$4,'Não Apagar'!$C$5,'Não Apagar'!$C$6,'Não Apagar'!$C$7,'Não Apagar'!$C$8,'Não Apagar'!$C$9) -> Segunda-feira | I13: =((H13-E13)-(G13-F13))*24 -> 0 | J13: =MAX(0,MIN(I13,'Não Apagar'!$J$3)) -> 0 | K13: =MAX(0,I13-'Não Apagar'!$J$3) -> 0 | L13: =L12+K13+D8 -> 0 | P13: 1
A14: 1 | C14: =C13+1 -> 45660 | D14: =CHOOSE(WEEKDAY(C14,2),'Não Apagar'!$C$3,'Não Apagar'!$C$4,'Não Apagar'!$C$5,'Não Apagar'!$C$6,'Não Apagar'!$C$7,'Não Apagar'!$C$8,'Não Apagar'!$C$9) -> Sexta-feira | I14: =((H14-E14)-(G14-F14))*24 -> 0 | J14: =MAX(0,MIN(I14,'Não Apagar'!$J$3)) -> 0 | K14: =MAX(0,I14-'Não Apagar'!$J$3) -> 0 | L14: =L13+K14 -> 0 | P14: 1
A15: 1 | C15: =C14+1 -> 45661 | D15: =CHOOSE(WEEKDAY(C15,2),'Não Apagar'!$C$3,'Não Apagar'!$C$4,'Não Apagar'!$C$5,'Não Apagar'!$C$6,'Não Apagar'!$C$7,'Não Apagar'!$C$8,'Não Apagar'!$C$9) -> Sábado | P15: 1
A16: 1 | C16: =C15+1 -> 45662 | D16: =CHOOSE(WEEKDAY(C16,2),'Não Apagar'!$C$3,'Não Apagar'!$C$4,'Não Apagar'!$C$5,'Não Apagar'!$C$6,'Não Apagar'!$C$7,'Não Apagar'!$C$8,'Não Apagar'!$C$9) -> Domingo | P16: 1
A17: 1 | C17: =C16+1 -> 45663 | D17: =CHOOSE(WEEKDAY(C17,2),'Não Apagar'!$C$3,'Não Apagar'!$C$4,'Não Apagar'!$C$5,'Não Apagar'!$C$6,'Não Apagar'!$C$7,'Não Apagar'!$C$8,'Não Apagar'!$C$9) -> Segunda-feira | I17: =((H17-E17)-(G17-F17))*24 -> 0 | J17: =MAX(0,MIN(I17,'Não Apagar'!$J$3)) -> 0 | K17: =MAX(0,I17-'Não Apagar'!$J$3) -> 0 | L17: =L14+K17 -> 0 | P17: 1
A18: 1 | C18: =C17+1 -> 45664 | D18: =CHOOSE(WEEKDAY(C18,2),'Não Apagar'!$C$3,'Não Apagar'!$C$4,'Não Apagar'!$C$5,'Não Apagar'!$C$6,'Não Apagar'!$C$7,'Não Apagar'!$C$8,'Não Apagar'!$C$9) -> Terça-feira | I18: =((H18-E18)-(G18-F18))*24 -> 0 | J18: =MAX(0,MIN(I18,'Não Apagar'!$J$3)) -> 0 | K18: =MAX(0,I18-'Não Apagar'!$J$3) -> 0 | L18: =L17+K18 -> 0 | P18: 1
A19: 1 | C19: =C18+1 -> 45665 | D19: =CHOOSE(WEEKDAY(C19,2),'Não Apagar'!$C$3,'Não Apagar'!$C$4,'Não Apagar'!$C$5,'Não Apagar'!$C$6,'Não Apagar'!$C$7,'Não Apagar'!$C$8,'Não Apagar'!$C$9) -> Quarta-feira | I19: =((H19-E19)-(G19-F19))*24 -> 0 | J19: =MAX(0,MIN(I19,'Não Apagar'!$J$3)) -> 0 | K19: =MAX(0,I19-'Não Apagar'!$J$3) -> 0 | L19: =L18+K19 -> 0 | P19: 1
A20: 1 | C20: =C19+1 -> 45666 | D20: =CHOOSE(WEEKDAY(C20,2),'Não Apagar'!$C$3,'Não Apagar'!$C$4,'Não Apagar'!$C$5,'Não Apagar'!$C$6,'Não Apagar'!$C$7,'Não Apagar'!$C$8,'Não Apagar'!$C$9) -> Segunda-feira | I20: =((H20-E20)-(G20-F20))*24 -> 0 | J20: =MAX(0,MIN(I20,'Não Apagar'!$J$3)) -> 0 | K20: =MAX(0,I20-'Não Apagar'!$J$3) -> 0 | L20: =L19+K20 -> 0 | P20: 1
A21: 1 | C21: =C20+1 -> 45667 | D21: =CHOOSE(WEEKDAY(C21,2),'Não Apagar'!$C$3,'Não Apagar'!$C$4,'Não Apagar'!$C$5,'Não Apagar'!$C$6,'Não Apagar'!$C$7,'Não Apagar'!$C$8,'Não Apagar'!$C$9) -> Sexta-feira | I21: =((H21-E21)-(G21-F21))*24 -> 0 | J21: =MAX(0,MIN(I21,'Não Apagar'!$J$3)) -> 0 | K21: =MAX(0,I21-'Não Apagar'!$J$3) -> 0 | L21: =L20+K21 -> 0 | P21: 1
A22: 1 | C22: =C21+1 -> 45668 | D22: =CHOOSE(WEEKDAY(C22,2),'Não Apagar'!$C$3,'Não Apagar'!$C$4,'Não Apagar'!$C$5,'Não Apagar'!$C$6,'Não Apagar'!$C$7,'Não Apagar'!$C$8,'Não Apagar'!$C$9) -> Sábado | P22: 1
A23: 1 | C23: =C22+1 -> 45669 | D23: =CHOOSE(WEEKDAY(C23,2),'Não Apagar'!$C$3,'Não Apagar'!$C$4,'Não Apagar'!$C$5,'Não Apagar'!$C$6,'Não Apagar'!$C$7,'Não Apagar'!$C$8,'Não Apagar'!$C$9) -> Domingo | P23: 1
A24: 1 | C24: =C23+1 -> 45670 | D24: =CHOOSE(WEEKDAY(C24,2),'Não Apagar'!$C$3,'Não Apagar'!$C$4,'Não Apagar'!$C$5,'Não Apagar'!$C$6,'Não Apagar'!$C$7,'Não Apagar'!$C$8,'Não Apagar'!$C$9) -> Segunda-feira | I24: =((H24-E24)-(G24-F24))*24 -> 0 | J24: =MAX(0,MIN(I24,'Não Apagar'!$J$3)) -> 0 | K24: =MAX(0,I24-'Não Apagar'!$J$3) -> 0 | L24: =L21+K24 -> 0 | P24: 1
A25: 1 | C25: =C24+1 -> 45671 | D25: =CHOOSE(WEEKDAY(C25,2),'Não Apagar'!$C$3,'Não Apagar'!$C$4,'Não Apagar'!$C$5,'Não Apagar'!$C$6,'Não Apagar'!$C$7,'Não Apagar'!$C$8,'Não Apagar'!$C$9) -> Terça-feira | I25: =((H25-E25)-(G25-F25))*24 -> 0 | J25: =MAX(0,MIN(I25,'Não Apagar'!$J$3)) -> 0 | K25: =MAX(0,I25-'Não Apagar'!$J$3) -> 0 | L25: =L24+K25 -> 0 | P25: 1
A26: 1 | C26: =C25+1 -> 45672 | D26: =CHOOSE(WEEKDAY(C26,2),'Não Apagar'!$C$3,'Não Apagar'!$C$4,'Não Apagar'!$C$5,'Não Apagar'!$C$6,'Não Apagar'!$C$7,'Não Apagar'!$C$8,'Não Apagar'!$C$9) -> Quarta-feira | I26: =((H26-E26)-(G26-F26))*24 -> 0 | J26: =MAX(0,MIN(I26,'Não Apagar'!$J$3)) -> 0 | K26: =MAX(0,I26-'Não Apagar'!$J$3) -> 0 | L26: =L25+K26 -> 0 | P26: 1
A27: 1 | C27: =C26+1 -> 45673 | D27: =CHOOSE(WEEKDAY(C27,2),'Não Apagar'!$C$3,'Não Apagar'!$C$4,'Não Apagar'!$C$5,'Não Apagar'!$C$6,'Não Apagar'!$C$7,'Não Apagar'!$C$8,'Não Apagar'!$C$9) -> Segunda-feira | I27: =((H27-E27)-(G27-F27))*24 -> 0 | J27: =MAX(0,MIN(I27,'Não Apagar'!$J$3)) -> 0 | K27: =MAX(0,I27-'Não Apagar'!$J$3) -> 0 | L27: =L26+K27 -> 0 | P27: 1
A28: 1 | C28: =C27+1 -> 45674 | D28: =CHOOSE(WEEKDAY(C28,2),'Não Apagar'!$C$3,'Não Apagar'!$C$4,'Não Apagar'!$C$5,'Não Apagar'!$C$6,'Não Apagar'!$C$7,'Não Apagar'!$C$8,'Não Apagar'!$C$9) -> Sexta-feira | I28: =((H28-E28)-(G28-F28))*24 -> 0 | J28: =MAX(0,MIN(I28,'Não Apagar'!$J$3)) -> 0 | K28: =MAX(0,I28-'Não Apagar'!$J$3) -> 0 | L28: =L27+K28 -> 0 | P28: 1
A29: 1 | C29: =C28+1 -> 45675 | D29: =CHOOSE(WEEKDAY(C29,2),'Não Apagar'!$C$3,'Não Apagar'!$C$4,'Não Apagar'!$C$5,'Não Apagar'!$C$6,'Não Apagar'!$C$7,'Não Apagar'!$C$8,'Não Apagar'!$C$9) -> Sábado | P29: 1
A30: 1 | C30: =C29+1 -> 45676 | D30: =CHOOSE(WEEKDAY(C30,2),'Não Apagar'!$C$3,'Não Apagar'!$C$4,'Não Apagar'!$C$5,'Não Apagar'!$C$6,'Não Apagar'!$C$7,'Não Apagar'!$C$8,'Não Apagar'!$C$9) -> Domingo | P30: 1
A31: 1 | C31: =C30+1 -> 45677 | D31: =CHOOSE(WEEKDAY(C31,2),'Não Apagar'!$C$3,'Não Apagar'!$C$4,'Não Apagar'!$C$5,'Não Apagar'!$C$6,'Não Apagar'!$C$7,'Não Apagar'!$C$8,'Não Apagar'!$C$9) -> Segunda-feira | I31: =((H31-E31)-(G31-F31))*24 -> 0 | J31: =MAX(0,MIN(I31,'Não Apagar'!$J$3)) -> 0 | K31: =MAX(0,I31-'Não Apagar'!$J$3) -> 0 | L31: =L28+K31 -> 0 | P31: 1
A32: 1 | C32: =C31+1 -> 45678 | D32: =CHOOSE(WEEKDAY(C32,2),'Não Apagar'!$C$3,'Não Apagar'!$C$4,'Não Apagar'!$C$5,'Não Apagar'!$C$6,'Não Apagar'!$C$7,'Não Apagar'!$C$8,'Não Apagar'!$C$9) -> Terça-feira | I32: =((H32-E32)-(G32-F32))*24 -> 0 | J32: =MAX(0,MIN(I32,'Não Apagar'!$J$3)) -> 0 | K32: =MAX(0,I32-'Não Apagar'!$J$3) -> 0 | L32: =L31+K32 -> 0 | P32: 1
A33: 1 | C33: =C32+1 -> 45679 | D33: =CHOOSE(WEEKDAY(C33,2),'Não Apagar'!$C$3,'Não Apagar'!$C$4,'Não Apagar'!$C$5,'Não Apagar'!$C$6,'Não Apagar'!$C$7,'Não Apagar'!$C$8,'Não Apagar'!$C$9) -> Quarta-feira | I33: =((H33-E33)-(G33-F33))*24 -> 0 | J33: =MAX(0,MIN(I33,'Não Apagar'!$J$3)) -> 0 | K33: =MAX(0,I33-'Não Apagar'!$J$3) -> 0 | L33: =L32+K33 -> 0 | P33: 1
A34: 1 | C34: =C33+1 -> 45680 | D34: =CHOOSE(WEEKDAY(C34,2),'Não Apagar'!$C$3,'Não Apagar'!$C$4,'Não Apagar'!$C$5,'Não Apagar'!$C$6,'Não Apagar'!$C$7,'Não Apagar'!$C$8,'Não Apagar'!$C$9) -> Segunda-feira | I34: =((H34-E34)-(G34-F34))*24 -> 0 | J34: =MAX(0,MIN(I34,'Não Apagar'!$J$3)) -> 0 | K34: =MAX(0,I34-'Não Apagar'!$J$3) -> 0 | L34: =L33+K34 -> 0 | P34: 1
A35: 1 | C35: =C34+1 -> 45681 | D35: =CHOOSE(WEEKDAY(C35,2),'Não Apagar'!$C$3,'Não Apagar'!$C$4,'Não Apagar'!$C$5,'Não Apagar'!$C$6,'Não Apagar'!$C$7,'Não Apagar'!$C$8,'Não Apagar'!$C$9) -> Sexta-feira | I35: =((H35-E35)-(G35-F35))*24 -> 0 | J35: =MAX(0,MIN(I35,'Não Apagar'!$J$3)) -> 0 | K35: =MAX(0,I35-'Não Apagar'!$J$3) -> 0 | L35: =L34+K35 -> 0 | P35: 1
A36: 1 | C36: =C35+1 -> 45682 | D36: =CHOOSE(WEEKDAY(C36,2),'Não Apagar'!$C$3,'Não Apagar'!$C$4,'Não Apagar'!$C$5,'Não Apagar'!$C$6,'Não Apagar'!$C$7,'Não Apagar'!$C$8,'Não Apagar'!$C$9) -> Sábado | P36: 1
A37: 1 | C37: =C36+1 -> 45683 | D37: =CHOOSE(WEEKDAY(C37,2),'Não Apagar'!$C$3,'Não Apagar'!$C$4,'Não Apagar'!$C$5,'Não Apagar'!$C$6,'Não Apagar'!$C$7,'Não Apagar'!$C$8,'Não Apagar'!$C$9) -> Domingo | P37: 1
A38: 1 | C38: =C37+1 -> 45684 | D38: =CHOOSE(WEEKDAY(C38,2),'Não Apagar'!$C$3,'Não Apagar'!$C$4,'Não Apagar'!$C$5,'Não Apagar'!$C$6,'Não Apagar'!$C$7,'Não Apagar'!$C$8,'Não Apagar'!$C$9) -> Segunda-feira | I38: =((H38-E38)-(G38-F38))*24 -> 0 | J38: =MAX(0,MIN(I38,'Não Apagar'!$J$3)) -> 0 | K38: =MAX(0,I38-'Não Apagar'!$J$3) -> 0 | L38: =IF(H38=0,L35,L35+K38-MAX(0,'Não Apagar'!$J$3-I38)) -> 0 | P38: 1
A39: 1 | C39: =C38+1 -> 45685 | D39: =CHOOSE(WEEKDAY(C39,2),'Não Apagar'!$C$3,'Não Apagar'!$C$4,'Não Apagar'!$C$5,'Não Apagar'!$C$6,'Não Apagar'!$C$7,'Não Apagar'!$C$8,'Não Apagar'!$C$9) -> Terça-feira | I39: =((H39-E39)-(G39-F39))*24 -> 0 | J39: =MAX(0,MIN(I39,'Não Apagar'!$J$3)) -> 0 | K39: =MAX(0,I39-'Não Apagar'!$J$3) -> 0 | L39: =IF(H39=0,L38,L38+K39-MAX(0,'Não Apagar'!$J$3-I39)) -> 0 | P39: 1
A40: 1 | C40: =C39+1 -> 45686 | D40: =CHOOSE(WEEKDAY(C40,2),'Não Apagar'!$C$3,'Não Apagar'!$C$4,'Não Apagar'!$C$5,'Não Apagar'!$C$6,'Não Apagar'!$C$7,'Não Apagar'!$C$8,'Não Apagar'!$C$9) -> Quarta-feira | I40: =((H40-E40)-(G40-F40))*24 -> 0 | J40: =MAX(0,MIN(I40,'Não Apagar'!$J$3)) -> 0 | K40: =MAX(0,I40-'Não Apagar'!$J$3) -> 0 | L40: =IF(H40=0,L39,L39+K40-MAX(0,'Não Apagar'!$J$3-I40)) -> 0 | P40: 1
A41: 1 | C41: =C40+1 -> 45687 | D41: =CHOOSE(WEEKDAY(C41,2),'Não Apagar'!$C$3,'Não Apagar'!$C$4,'Não Apagar'!$C$5,'Não Apagar'!$C$6,'Não Apagar'!$C$7,'Não Apagar'!$C$8,'Não Apagar'!$C$9) -> Segunda-feira | I41: =((H41-E41)-(G41-F41))*24 -> 0 | J41: =MAX(0,MIN(I41,'Não Apagar'!$J$3)) -> 0 | K41: =MAX(0,I41-'Não Apagar'!$J$3) -> 0 | L41: =IF(H41=0,L40,L40+K41-MAX(0,'Não Apagar'!$J$3-I41)) -> 0 | P41: 1
...

Sheet Fev.25
A1: 1 | B1: 1 | C1: 1 | D1: 1 | E1: 1 | F1: 1 | G1: 1 | H1: 1 | I1: 1 | J1: 1 | K1: 1 | L1: 1 | M1: 1 | N1: 1 | O1: 1 | P1: 1
C3: Bluzz Saúde Ltda.
A4: 1 | C4: CNPJ | D4: 54.557.861/0001-02 | P4: 1
A5: 1 | C5: Colaborador | P5: 1
A6: 1 | C6: Mês Competência | D6: Fev.25 | P6: 1
A7: 1 | P7: 1
A8: 1 | P8: 1
A9: 1 | P9: 1
A10: 1 | P10: 1
A11: 1 | C11: CONTROLE DE PONTO | P11: 1
A12: 1 | C12: Data | D12: Dia da semana | E12: Entrada | F12: Saída Almoço | G12: Retorno Almoço | H12: Saída | I12: Horas Trabalhadas | J12: Horas Normais | K12: Horas Extras | L12: Banco de Horas | P12: 1
A13: 1 | C13: 45689 | D13: =CHOOSE(WEEKDAY(C13,2),'Não Apagar'!$C$3,'Não Apagar'!$C$4,'Não Apagar'!$C$5,'Não Apagar'!$C$6,'Não Apagar'!$C$7,'Não Apagar'!$C$8,'Não Apagar'!$C$9) -> Sábado | P13: 1
A14: 1 | C14: =C13+1 -> 45690 | D14: =CHOOSE(WEEKDAY(C14,2),'Não Apagar'!$C$3,'Não Apagar'!$C$4,'Não Apagar'!$C$5,'Não Apagar'!$C$6,'Não Apagar'!$C$7,'Não Apagar'!$C$8,'Não Apagar'!$C$9) -> Domingo | P14: 1
A15: 1 | C15: =C14+1 -> 45691 | D15: =CHOOSE(WEEKDAY(C15,2),'Não Apagar'!$C$3,'Não Apagar'!$C$4,'Não Apagar'!$C$5,'Não Apagar'!$C$6,'Não Apagar'!$C$7,'Não Apagar'!$C$8,'Não Apagar'!$C$9) -> Segunda-feira | I15: =((H15-E15)-(G15-F15))*24 -> 0 | J15: =MAX(0,MIN(I15,'Não Apagar'!$J$3)) -> 0 | K15: =MAX(0,I15-'Não Apagar'!$J$3) -> 0 | L15: =K15+Jan.25!L44 -> 0 | P15: 1
A16: 1 | C16: =C15+1 -> 45692 | D16: =CHOOSE(WEEKDAY(C16,2),'Não Apagar'!$C$3,'Não Apagar'!$C$4,'Não Apagar'!$C$5,'Não Apagar'!$C$6,'Não Apagar'!$C$7,'Não Apagar'!$C$8,'Não Apagar'!$C$9) -> Terça-feira | I16: =((H16-E16)-(G16-F16))*24 -> 0 | J16: =MAX(0,MIN(I16,'Não Apagar'!$J$3)) -> 0 | K16: =MAX(0,I16-'Não Apagar'!$J$3) -> 0 | L16: =L15+K16 -> 0 | P16: 1
A17: 1 | C17: =C16+1 -> 45693 | D17: =CHOOSE(WEEKDAY(C17,2),'Não Apagar'!$C$3,'Não Apagar'!$C$4,'Não Apagar'!$C$5,'Não Apagar'!$C$6,'Não Apagar'!$C$7,'Não Apagar'!$C$8,'Não Apagar'!$C$9) -> Quarta-feira | I17: =((H17-E17)-(G17-F17))*24 -> 0 | J17: =MAX(0,MIN(I17,'Não Apagar'!$J$3)) -> 0 | K17: =MAX(0,I17-'Não Apagar'!$J$3) -> 0 | L17: =L16+K17 -> 0 | P17: 1
A18: 1 | C18: =C17+1 -> 45694 | D18: =CHOOSE(WEEKDAY(C18,2),'Não Apagar'!$C$3,'Não Apagar'!$C$4,'Não Apagar'!$C$5,'Não Apagar'!$C$6,'Não Apagar'!$C$7,'Não Apagar'!$C$8,'Não Apagar'!$C$9) -> Segunda-feira | I18: =((H18-E18)-(G18-F18))*24 -> 0 | J18: =MAX(0,MIN(I18,'Não Apagar'!$J$3)) -> 0 | K18: =MAX(0,I18-'Não Apagar'!$J$3) -> 0 | L18: =L17+K18 -> 0 | P18: 1
A19: 1 | C19: =C18+1 -> 45695 | D19: =CHOOSE(WEEKDAY(C19,2),'Não Apagar'!$C$3,'Não Apagar'!$C$4,'Não Apagar'!$C$5,'Não Apagar'!$C$6,'Não Apagar'!$C$7,'Não Apagar'!$C$8,'Não Apagar'!$C$9) -> Sexta-feira | I19: =((H19-E19)-(G19-F19))*24 -> 0 | J19: =MAX(0,MIN(I19,'Não Apagar'!$J$3)) -> 0 | K19: =MAX(0,I19-'Não Apagar'!$J$3) -> 0 | L19: =L18+K19 -> 0 | P19: 1
A20: 1 | C20: =C19+1 -> 45696 | D20: =CHOOSE(WEEKDAY(C20,2),'Não Apagar'!$C$3,'Não Apagar'!$C$4,'Não Apagar'!$C$5,'Não Apagar'!$C$6,'Não Apagar'!$C$7,'Não Apagar'!$C$8,'Não Apagar'!$C$9) -> Sábado | P20: 1
A21: 1 | C21: =C20+1 -> 45697 | D21: =CHOOSE(WEEKDAY(C21,2),'Não Apagar'!$C$3,'Não Apagar'!$C$4,'Não Apagar'!$C$5,'Não Apagar'!$C$6,'Não Apagar'!$C$7,'Não Apagar'!$C$8,'Não Apagar'!$C$9) -> Domingo | P21: 1
A22: 1 | C22: =C21+1 -> 45698 | D22: =CHOOSE(WEEKDAY(C22,2),'Não Apagar'!$C$3,'Não Apagar'!$C$4,'Não Apagar'!$C$5,'Não Apagar'!$C$6,'Não Apagar'!$C$7,'Não Apagar'!$C$8,'Não Apagar'!$C$9) -> Segunda-feira | I22: =((H22-E22)-(G22-F22))*24 -> 0 | J22: =MAX(0,MIN(I22,'Não Apagar'!$J$3)) -> 0 | K22: =MAX(0,I22-'Não Apagar'!$J$3) -> 0 | L22: =L19+K22 -> 0 | P22: 1
A23: 1 | C23: =C22+1 -> 45699 | D23: =CHOOSE(WEEKDAY(C23,2),'Não Apagar'!$C$3,'Não Apagar'!$C$4,'Não Apagar'!$C$5,'Não Apagar'!$C$6,'Não Apagar'!$C$7,'Não Apagar'!$C$8,'Não Apagar'!$C$9) -> Terça-feira | I23: =((H23-E23)-(G23-F23))*24 -> 0 | J23: =MAX(0,MIN(I23,'Não Apagar'!$J$3)) -> 0 | K23: =MAX(0,I23-'Não Apagar'!$J$3) -> 0 | L23: =L22+K23 -> 0 | P23: 1
A24: 1 | C24: =C23+1 -> 45700 | D24: =CHOOSE(WEEKDAY(C24,2),'Não Apagar'!$C$3,'Não Apagar'!$C$4,'Não Apagar'!$C$5,'Não Apagar'!$C$6,'Não Apagar'!$C$7,'Não Apagar'!$C$8,'Não Apagar'!$C$9) -> Quarta-feira | I24: =((H24-E24)-(G24-F24))*24 -> 0 | J24: =MAX(0,MIN(I24,'Não Apagar'!$J$3)) -> 0 | K24: =MAX(0,I24-'Não Apagar'!$J$3) -> 0 | L24: =L23+K24 -> 0 | P24: 1
A25: 1 | C25: =C24+1 -> 45701 | D25: =CHOOSE(WEEKDAY(C25,2),'Não Apagar'!$C$3,'Não Apagar'!$C$4,'Não Apagar'!$C$5,'Não Apagar'!$C$6,'Não Apagar'!$C$7,'Não Apagar'!$C$8,'Não Apagar'!$C$9) -> Segunda-feira | I25: =((H25-E25)-(G25-F25))*24 -> 0 | J25: =MAX(0,MIN(I25,'Não Apagar'!$J$3)) -> 0 | K25: =MAX(0,I25-'Não Apagar'!$J$3) -> 0 | L25: =L24+K25 -> 0 | P25: 1
A26: 1 | C26: =C25+1 -> 45702 | D26: =CHOOSE(WEEKDAY(C26,2),'Não Apagar'!$C$3,'Não Apagar'!$C$4,'Não Apagar'!$C$5,'Não Apagar'!$C$6,'Não Apagar'!$C$7,'Não Apagar'!$C$8,'Não Apagar'!$C$9) -> Sexta-feira | I26: =((H26-E26)-(G26-F26))*24 -> 0 | J26: =MAX(0,MIN(I26,'Não Apagar'!$J$3)) -> 0 | K26: =MAX(0,I26-'Não Apagar'!$J$3) -> 0 | L26: =L25+K26 -> 0 | P26: 1
A27: 1 | C27: =C26+1 -> 45703 | D27: =CHOOSE(WEEKDAY(C27,2),'Não Apagar'!$C$3,'Não Apagar'!$C$4,'Não Apagar'!$C$5,'Não Apagar'!$C$6,'Não Apagar'!$C$7,'Não Apagar'!$C$8,'Não Apagar'!$C$9) -> Sábado | P27: 1
A28: 1 | C28: =C27+1 -> 45704 | D28: =CHOOSE(WEEKDAY(C28,2),'Não Apagar'!$C$3,'Não Apagar'!$C$4,'Não Apagar'!$C$5,'Não Apagar'!$C$6,'Não Apagar'!$C$7,'Não Apagar'!$C$8,'Não Apagar'!$C$9) -> Domingo | P28: 1
A29: 1 | C29: =C28+1 -> 45705 | D29: =CHOOSE(WEEKDAY(C29,2),'Não Apagar'!$C$3,'Não Apagar'!$C$4,'Não Apagar'!$C$5,'Não Apagar'!$C$6,'Não Apagar'!$C$7,'Não Apagar'!$C$8,'Não Apagar'!$C$9) -> Segunda-feira | I29: =((H29-E29)-(G29-F29))*24 -> 0 | J29: =MAX(0,MIN(I29,'Não Apagar'!$J$3)) -> 0 | K29: =MAX(0,I29-'Não Apagar'!$J$3) -> 0 | L29: =L26+K29 -> 0 | P29: 1
A30: 1 | C30: =C29+1 -> 45706 | D30: =CHOOSE(WEEKDAY(C30,2),'Não Apagar'!$C$3,'Não Apagar'!$C$4,'Não Apagar'!$C$5,'Não Apagar'!$C$6,'Não Apagar'!$C$7,'Não Apagar'!$C$8,'Não Apagar'!$C$9) -> Terça-feira | I30: =((H30-E30)-(G30-F30))*24 -> 0 | J30: =MAX(0,MIN(I30,'Não Apagar'!$J$3)) -> 0 | K30: =MAX(0,I30-'Não Apagar'!$J$3) -> 0 | L30: =L29+K30 -> 0 | P30: 1
A31: 1 | C31: =C30+1 -> 45707 | D31: =CHOOSE(WEEKDAY(C31,2),'Não Apagar'!$C$3,'Não Apagar'!$C$4,'Não Apagar'!$C$5,'Não Apagar'!$C$6,'Não Apagar'!$C$7,'Não Apagar'!$C$8,'Não Apagar'!$C$9) -> Quarta-feira | I31: =((H31-E31)-(G31-F31))*24 -> 0 | J31: =MAX(0,MIN(I31,'Não Apagar'!$J$3)) -> 0 | K31: =MAX(0,I31-'Não Apagar'!$J$3) -> 0 | L31: =L30+K31 -> 0 | P31: 1
A32: 1 | C32: =C31+1 -> 45708 | D32: =CHOOSE(WEEKDAY(C32,2),'Não Apagar'!$C$3,'Não Apagar'!$C$4,'Não Apagar'!$C$5,'Não Apagar'!$C$6,'Não Apagar'!$C$7,'Não Apagar'!$C$8,'Não Apagar'!$C$9) -> Segunda-feira | I32: =((H32-E32)-(G32-F32))*24 -> 0 | J32: =MAX(0,MIN(I32,'Não Apagar'!$J$3)) -> 0 | K32: =MAX(0,I32-'Não Apagar'!$J$3) -> 0 | L32: =L31+K32 -> 0 | P32: 1
A33: 1 | C33: =C32+1 -> 45709 | D33: =CHOOSE(WEEKDAY(C33,2),'Não Apagar'!$C$3,'Não Apagar'!$C$4,'Não Apagar'!$C$5,'Não Apagar'!$C$6,'Não Apagar'!$C$7,'Não Apagar'!$C$8,'Não Apagar'!$C$9) -> Sexta-feira | I33: =((H33-E33)-(G33-F33))*24 -> 0 | J33: =MAX(0,MIN(I33,'Não Apagar'!$J$3)) -> 0 | K33: =MAX(0,I33-'Não Apagar'!$J$3) -> 0 | L33: =L32+K33 -> 0 | P33: 1
A34: 1 | C34: =C33+1 -> 45710 | D34: =CHOOSE(WEEKDAY(C34,2),'Não Apagar'!$C$3,'Não Apagar'!$C$4,'Não Apagar'!$C$5,'Não Apagar'!$C$6,'Não Apagar'!$C$7,'Não Apagar'!$C$8,'Não Apagar'!$C$9) -> Sábado | P34: 1
A35: 1 | C35: =C34+1 -> 45711 | D35: =CHOOSE(WEEKDAY(C35,2),'Não Apagar'!$C$3,'Não Apagar'!$C$4,'Não Apagar'!$C$5,'Não Apagar'!$C$6,'Não Apagar'!$C$7,'Não Apagar'!$C$8,'Não Apagar'!$C$9) -> Domingo | P35: 1
A36: 1 | C36: =C35+1 -> 45712 | D36: =CHOOSE(WEEKDAY(C36,2),'Não Apagar'!$C$3,'Não Apagar'!$C$4,'Não Apagar'!$C$5,'Não Apagar'!$C$6,'Não Apagar'!$C$7,'Não Apagar'!$C$8,'Não Apagar'!$C$9) -> Segunda-feira | I36: =((H36-E36)-(G36-F36))*24 -> 0 | J36: =MAX(0,MIN(I36,'Não Apagar'!$J$3)) -> 0 | K36: =MAX(0,I36-'Não Apagar'!$J$3) -> 0 | L36: =L33+K36 -> 0 | P36: 1
A37: 1 | C37: =C36+1 -> 45713 | D37: =CHOOSE(WEEKDAY(C37,2),'Não Apagar'!$C$3,'Não Apagar'!$C$4,'Não Apagar'!$C$5,'Não Apagar'!$C$6,'Não Apagar'!$C$7,'Não Apagar'!$C$8,'Não Apagar'!$C$9) -> Terça-feira | I37: =((H37-E37)-(G37-F37))*24 -> 0 | J37: =MAX(0,MIN(I37,'Não Apagar'!$J$3)) -> 0 | K37: =MAX(0,I37-'Não Apagar'!$J$3) -> 0 | L37: =L36+K37 -> 0 | P37: 1
A38: 1 | C38: =C37+1 -> 45714 | D38: =CHOOSE(WEEKDAY(C38,2),'Não Apagar'!$C$3,'Não Apagar'!$C$4,'Não Apagar'!$C$5,'Não Apagar'!$C$6,'Não Apagar'!$C$7,'Não Apagar'!$C$8,'Não Apagar'!$C$9) -> Quarta-feira | I38: =((H38-E38)-(G38-F38))*24 -> 0 | J38: =MAX(0,MIN(I38,'Não Apagar'!$J$3)) -> 0 | K38: =MAX(0,I38-'Não Apagar'!$J$3) -> 0 | L38: =L37+K38 -> 0 | P38: 1
A39: 1 | C39: =C38+1 -> 45715 | D39: =CHOOSE(WEEKDAY(C39,2),'Não Apagar'!$C$3,'Não Apagar'!$C$4,'Não Apagar'!$C$5,'Não Apagar'!$C$6,'Não Apagar'!$C$7,'Não Apagar'!$C$8,'Não Apagar'!$C$9) -> Segunda-feira | I39: =((H39-E39)-(G39-F39))*24 -> 0 | J39: =MAX(0,MIN(I39,'Não Apagar'!$J$3)) -> 0 | K39: =MAX(0,I39-'Não Apagar'!$J$3) -> 0 | L39: =L38+K39 -> 0 | P39: 1
A40: 1 | C40: =C39+1 -> 45716 | D40: =CHOOSE(WEEKDAY(C40,2),'Não Apagar'!$C$3,'Não Apagar'!$C$4,'Não Apagar'!$C$5,'Não Apagar'!$C$6,'Não Apagar'!$C$7,'Não Apagar'!$C$8,'Não Apagar'!$C$9) -> Sexta-feira | I40: =((H40-E40)-(G40-F40))*24 -> 0 | J40: =MAX(0,MIN(I40,'Não Apagar'!$J$3)) -> 0 | K40: =MAX(0,I40-'Não Apagar'!$J$3) -> 0 | L40: =L39+K40 -> 0 | P40: 1
A41: 1 | P41: 1
...

Sheet Mar.25
A1: 1 | B1: 1 | C1: 1 | D1: 1 | E1: 1 | F1: 1 | G1: 1 | H1: 1 | I1: 1 | J1: 1 | K1: 1 | L1: 1 | M1: 1 | N1: 1 | O1: 1 | P1: 1
C3: Bluzz Saúde Ltda.
A4: 1 | C4: CNPJ | D4: 54.557.861/0001-02 | P4: 1
A5: 1 | C5: Colaborador | P5: 1
A6: 1 | C6: Mês Competência | D6: Mar.25 | P6: 1
A7: 1 | P7: 1
A8: 1 | P8: 1
A9: 1 | P9: 1
A10: 1 | P10: 1
A11: 1 | C11: DEZEMBRO - CONTROLE DE PONTO | P11: 1
A12: 1 | C12: Data | D12: Dia da semana | E12: Entrada | F12: Saída Almoço | G12: Retorno Almoço | H12: Saída | I12: Horas Trabalhadas | J12: Horas Normais | K12: Horas Extras | L12: Banco de Horas | P12: 1
A13: 1 | C13: 45717 | D13: =CHOOSE(WEEKDAY(C13,2),'Não Apagar'!$C$3,'Não Apagar'!$C$4,'Não Apagar'!$C$5,'Não Apagar'!$C$6,'Não Apagar'!$C$7,'Não Apagar'!$C$8,'Não Apagar'!$C$9) -> Sábado | P13: 1
A14: 1 | C14: =C13+1 -> 45718 | D14: =CHOOSE(WEEKDAY(C14,2),'Não Apagar'!$C$3,'Não Apagar'!$C$4,'Não Apagar'!$C$5,'Não Apagar'!$C$6,'Não Apagar'!$C$7,'Não Apagar'!$C$8,'Não Apagar'!$C$9) -> Domingo | P14: 1
A15: 1 | C15: =C14+1 -> 45719 | D15: =CHOOSE(WEEKDAY(C15,2),'Não Apagar'!$C$3,'Não Apagar'!$C$4,'Não Apagar'!$C$5,'Não Apagar'!$C$6,'Não Apagar'!$C$7,'Não Apagar'!$C$8,'Não Apagar'!$C$9) -> Segunda-feira | I15: =((H15-E15)-(G15-F15))*24 -> 0 | J15: =MAX(0,MIN(I15,'Não Apagar'!$J$3)) -> 0 | K15: =MAX(0,I15-'Não Apagar'!$J$3) -> 0 | L15: =K15+Fev.25!L45 -> 0 | P15: 1
A16: 1 | C16: =C15+1 -> 45720 | D16: =CHOOSE(WEEKDAY(C16,2),'Não Apagar'!$C$3,'Não Apagar'!$C$4,'Não Apagar'!$C$5,'Não Apagar'!$C$6,'Não Apagar'!$C$7,'Não Apagar'!$C$8,'Não Apagar'!$C$9) -> Terça-feira | I16: =((H16-E16)-(G16-F16))*24 -> 0 | J16: =MAX(0,MIN(I16,'Não Apagar'!$J$3)) -> 0 | K16: =MAX(0,I16-'Não Apagar'!$J$3) -> 0 | L16: =L15+K16 -> 0 | P16: 1
A17: 1 | C17: =C16+1 -> 45721 | D17: =CHOOSE(WEEKDAY(C17,2),'Não Apagar'!$C$3,'Não Apagar'!$C$4,'Não Apagar'!$C$5,'Não Apagar'!$C$6,'Não Apagar'!$C$7,'Não Apagar'!$C$8,'Não Apagar'!$C$9) -> Quarta-feira | I17: =((H17-E17)-(G17-F17))*24 -> 0 | J17: =MAX(0,MIN(I17,'Não Apagar'!$J$3)) -> 0 | K17: =MAX(0,I17-'Não Apagar'!$J$3) -> 0 | L17: =L16+K17 -> 0 | P17: 1
A18: 1 | C18: =C17+1 -> 45722 | D18: =CHOOSE(WEEKDAY(C18,2),'Não Apagar'!$C$3,'Não Apagar'!$C$4,'Não Apagar'!$C$5,'Não Apagar'!$C$6,'Não Apagar'!$C$7,'Não Apagar'!$C$8,'Não Apagar'!$C$9) -> Segunda-feira | I18: =((H18-E18)-(G18-F18))*24 -> 0 | J18: =MAX(0,MIN(I18,'Não Apagar'!$J$3)) -> 0 | K18: =MAX(0,I18-'Não Apagar'!$J$3) -> 0 | L18: =L17+K18 -> 0 | P18: 1
A19: 1 | C19: =C18+1 -> 45723 | D19: =CHOOSE(WEEKDAY(C19,2),'Não Apagar'!$C$3,'Não Apagar'!$C$4,'Não Apagar'!$C$5,'Não Apagar'!$C$6,'Não Apagar'!$C$7,'Não Apagar'!$C$8,'Não Apagar'!$C$9) -> Sexta-feira | I19: =((H19-E19)-(G19-F19))*24 -> 0 | J19: =MAX(0,MIN(I19,'Não Apagar'!$J$3)) -> 0 | K19: =MAX(0,I19-'Não Apagar'!$J$3) -> 0 | L19: =L18+K19 -> 0 | P19: 1
A20: 1 | C20: =C19+1 -> 45724 | D20: =CHOOSE(WEEKDAY(C20,2),'Não Apagar'!$C$3,'Não Apagar'!$C$4,'Não Apagar'!$C$5,'Não Apagar'!$C$6,'Não Apagar'!$C$7,'Não Apagar'!$C$8,'Não Apagar'!$C$9) -> Sábado | P20: 1
A21: 1 | C21: =C20+1 -> 45725 | D21: =CHOOSE(WEEKDAY(C21,2),'Não Apagar'!$C$3,'Não Apagar'!$C$4,'Não Apagar'!$C$5,'Não Apagar'!$C$6,'Não Apagar'!$C$7,'Não Apagar'!$C$8,'Não Apagar'!$C$9) -> Domingo | P21: 1
A22: 1 | C22: =C21+1 -> 45726 | D22: =CHOOSE(WEEKDAY(C22,2),'Não Apagar'!$C$3,'Não Apagar'!$C$4,'Não Apagar'!$C$5,'Não Apagar'!$C$6,'Não Apagar'!$C$7,'Não Apagar'!$C$8,'Não Apagar'!$C$9) -> Segunda-feira | I22: =((H22-E22)-(G22-F22))*24 -> 0 | J22: =MAX(0,MIN(I22,'Não Apagar'!$J$3)) -> 0 | K22: =MAX(0,I22-'Não Apagar'!$J$3) -> 0 | L22: =L19+K22 -> 0 | P22: 1
A23: 1 | C23: =C22+1 -> 45727 | D23: =CHOOSE(WEEKDAY(C23,2),'Não Apagar'!$C$3,'Não Apagar'!$C$4,'Não Apagar'!$C$5,'Não Apagar'!$C$6,'Não Apagar'!$C$7,'Não Apagar'!$C$8,'Não Apagar'!$C$9) -> Terça-feira | I23: =((H23-E23)-(G23-F23))*24 -> 0 | J23: =MAX(0,MIN(I23,'Não Apagar'!$J$3)) -> 0 | K23: =MAX(0,I23-'Não Apagar'!$J$3) -> 0 | L23: =L22+K23 -> 0 | P23: 1
A24: 1 | C24: =C23+1 -> 45728 | D24: =CHOOSE(WEEKDAY(C24,2),'Não Apagar'!$C$3,'Não Apagar'!$C$4,'Não Apagar'!$C$5,'Não Apagar'!$C$6,'Não Apagar'!$C$7,'Não Apagar'!$C$8,'Não Apagar'!$C$9) -> Quarta-feira | I24: =((H24-E24)-(G24-F24))*24 -> 0 | J24: =MAX(0,MIN(I24,'Não Apagar'!$J$3)) -> 0 | K24: =MAX(0,I24-'Não Apagar'!$J$3) -> 0 | L24: =L23+K24 -> 0 | P24: 1
A25: 1 | C25: =C24+1 -> 45729 | D25: =CHOOSE(WEEKDAY(C25,2),'Não Apagar'!$C$3,'Não Apagar'!$C$4,'Não Apagar'!$C$5,'Não Apagar'!$C$6,'Não Apagar'!$C$7,'Não Apagar'!$C$8,'Não Apagar'!$C$9) -> Segunda-feira | I25: =((H25-E25)-(G25-F25))*24 -> 0 | J25: =MAX(0,MIN(I25,'Não Apagar'!$J$3)) -> 0 | K25: =MAX(0,I25-'Não Apagar'!$J$3) -> 0 | L25: =L24+K25 -> 0 | P25: 1
A26: 1 | C26: =C25+1 -> 45730 | D26: =CHOOSE(WEEKDAY(C26,2),'Não Apagar'!$C$3,'Não Apagar'!$C$4,'Não Apagar'!$C$5,'Não Apagar'!$C$6,'Não Apagar'!$C$7,'Não Apagar'!$C$8,'Não Apagar'!$C$9) -> Sexta-feira | I26: =((H26-E26)-(G26-F26))*24 -> 0 | J26: =MAX(0,MIN(I26,'Não Apagar'!$J$3)) -> 0 | K26: =MAX(0,I26-'Não Apagar'!$J$3) -> 0 | L26: =L25+K26 -> 0 | P26: 1
A27: 1 | C27: =C26+1 -> 45731 | D27: =CHOOSE(WEEKDAY(C27,2),'Não Apagar'!$C$3,'Não Apagar'!$C$4,'Não Apagar'!$C$5,'Não Apagar'!$C$6,'Não Apagar'!$C$7,'Não Apagar'!$C$8,'Não Apagar'!$C$9) -> Sábado | P27: 1
A28: 1 | C28: =C27+1 -> 45732 | D28: =CHOOSE(WEEKDAY(C28,2),'Não Apagar'!$C$3,'Não Apagar'!$C$4,'Não Apagar'!$C$5,'Não Apagar'!$C$6,'Não Apagar'!$C$7,'Não Apagar'!$C$8,'Não Apagar'!$C$9) -> Domingo | P28: 1
A29: 1 | C29: =C28+1 -> 45733 | D29: =CHOOSE(WEEKDAY(C29,2),'Não Apagar'!$C$3,'Não Apagar'!$C$4,'Não Apagar'!$C$5,'Não Apagar'!$C$6,'Não Apagar'!$C$7,'Não Apagar'!$C$8,'Não Apagar'!$C$9) -> Segunda-feira | I29: =((H29-E29)-(G29-F29))*24 -> 0 | J29: =MAX(0,MIN(I29,'Não Apagar'!$J$3)) -> 0 | K29: =MAX(0,I29-'Não Apagar'!$J$3) -> 0 | L29: =L26+K29 -> 0 | P29: 1
A30: 1 | C30: =C29+1 -> 45734 | D30: =CHOOSE(WEEKDAY(C30,2),'Não Apagar'!$C$3,'Não Apagar'!$C$4,'Não Apagar'!$C$5,'Não Apagar'!$C$6,'Não Apagar'!$C$7,'Não Apagar'!$C$8,'Não Apagar'!$C$9) -> Terça-feira | I30: =((H30-E30)-(G30-F30))*24 -> 0 | J30: =MAX(0,MIN(I30,'Não Apagar'!$J$3)) -> 0 | K30: =MAX(0,I30-'Não Apagar'!$J$3) -> 0 | L30: =L29+K30 -> 0 | P30: 1
A31: 1 | C31: =C30+1 -> 45735 | D31: =CHOOSE(WEEKDAY(C31,2),'Não Apagar'!$C$3,'Não Apagar'!$C$4,'Não Apagar'!$C$5,'Não Apagar'!$C$6,'Não Apagar'!$C$7,'Não Apagar'!$C$8,'Não Apagar'!$C$9) -> Quarta-feira | I31: =((H31-E31)-(G31-F31))*24 -> 0 | J31: =MAX(0,MIN(I31,'Não Apagar'!$J$3)) -> 0 | K31: =MAX(0,I31-'Não Apagar'!$J$3) -> 0 | L31: =L30+K31 -> 0 | P31: 1
A32: 1 | C32: =C31+1 -> 45736 | D32: =CHOOSE(WEEKDAY(C32,2),'Não Apagar'!$C$3,'Não Apagar'!$C$4,'Não Apagar'!$C$5,'Não Apagar'!$C$6,'Não Apagar'!$C$7,'Não Apagar'!$C$8,'Não Apagar'!$C$9) -> Segunda-feira | I32: =((H32-E32)-(G32-F32))*24 -> 0 | J32: =MAX(0,MIN(I32,'Não Apagar'!$J$3)) -> 0 | K32: =MAX(0,I32-'Não Apagar'!$J$3) -> 0 | L32: =L31+K32 -> 0 | P32: 1
A33: 1 | C33: =C32+1 -> 45737 | D33: =CHOOSE(WEEKDAY(C33,2),'Não Apagar'!$C$3,'Não Apagar'!$C$4,'Não Apagar'!$C$5,'Não Apagar'!$C$6,'Não Apagar'!$C$7,'Não Apagar'!$C$8,'Não Apagar'!$C$9) -> Sexta-feira | I33: =((H33-E33)-(G33-F33))*24 -> 0 | J33: =MAX(0,MIN(I33,'Não Apagar'!$J$3)) -> 0 | K33: =MAX(0,I33-'Não Apagar'!$J$3) -> 0 | L33: =L32+K33 -> 0 | P33: 1
A34: 1 | C34: =C33+1 -> 45738 | D34: =CHOOSE(WEEKDAY(C34,2),'Não Apagar'!$C$3,'Não Apagar'!$C$4,'Não Apagar'!$C$5,'Não Apagar'!$C$6,'Não Apagar'!$C$7,'Não Apagar'!$C$8,'Não Apagar'!$C$9) -> Sábado | P34: 1
A35: 1 | C35: =C34+1 -> 45739 | D35: =CHOOSE(WEEKDAY(C35,2),'Não Apagar'!$C$3,'Não Apagar'!$C$4,'Não Apagar'!$C$5,'Não Apagar'!$C$6,'Não Apagar'!$C$7,'Não Apagar'!$C$8,'Não Apagar'!$C$9) -> Domingo | P35: 1
A36: 1 | C36: =C35+1 -> 45740 | D36: =CHOOSE(WEEKDAY(C36,2),'Não Apagar'!$C$3,'Não Apagar'!$C$4,'Não Apagar'!$C$5,'Não Apagar'!$C$6,'Não Apagar'!$C$7,'Não Apagar'!$C$8,'Não Apagar'!$C$9) -> Segunda-feira | I36: =((H36-E36)-(G36-F36))*24 -> 0 | J36: =MAX(0,MIN(I36,'Não Apagar'!$J$3)) -> 0 | K36: =MAX(0,I36-'Não Apagar'!$J$3) -> 0 | L36: =L33+K36 -> 0 | P36: 1
A37: 1 | C37: =C36+1 -> 45741 | D37: =CHOOSE(WEEKDAY(C37,2),'Não Apagar'!$C$3,'Não Apagar'!$C$4,'Não Apagar'!$C$5,'Não Apagar'!$C$6,'Não Apagar'!$C$7,'Não Apagar'!$C$8,'Não Apagar'!$C$9) -> Terça-feira | I37: =((H37-E37)-(G37-F37))*24 -> 0 | J37: =MAX(0,MIN(I37,'Não Apagar'!$J$3)) -> 0 | K37: =MAX(0,I37-'Não Apagar'!$J$3) -> 0 | L37: =L36+K37 -> 0 | P37: 1
A38: 1 | C38: =C37+1 -> 45742 | D38: =CHOOSE(WEEKDAY(C38,2),'Não Apagar'!$C$3,'Não Apagar'!$C$4,'Não Apagar'!$C$5,'Não Apagar'!$C$6,'Não Apagar'!$C$7,'Não Apagar'!$C$8,'Não Apagar'!$C$9) -> Quarta-feira | I38: =((H38-E38)-(G38-F38))*24 -> 0 | J38: =MAX(0,MIN(I38,'Não Apagar'!$J$3)) -> 0 | K38: =MAX(0,I38-'Não Apagar'!$J$3) -> 0 | L38: =L37+K38 -> 0 | P38: 1
A39: 1 | C39: =C38+1 -> 45743 | D39: =CHOOSE(WEEKDAY(C39,2),'Não Apagar'!$C$3,'Não Apagar'!$C$4,'Não Apagar'!$C$5,'Não Apagar'!$C$6,'Não Apagar'!$C$7,'Não Apagar'!$C$8,'Não Apagar'!$C$9) -> Segunda-feira | I39: =((H39-E39)-(G39-F39))*24 -> 0 | J39: =MAX(0,MIN(I39,'Não Apagar'!$J$3)) -> 0 | K39: =MAX(0,I39-'Não Apagar'!$J$3) -> 0 | L39: =L38+K39 -> 0 | P39: 1
A40: 1 | C40: =C39+1 -> 45744 | D40: =CHOOSE(WEEKDAY(C40,2),'Não Apagar'!$C$3,'Não Apagar'!$C$4,'Não Apagar'!$C$5,'Não Apagar'!$C$6,'Não Apagar'!$C$7,'Não Apagar'!$C$8,'Não Apagar'!$C$9) -> Sexta-feira | I40: =((H40-E40)-(G40-F40))*24 -> 0 | J40: =MAX(0,MIN(I40,'Não Apagar'!$J$3)) -> 0 | K40: =MAX(0,I40-'Não Apagar'!$J$3) -> 0 | L40: =L39+K40 -> 0 | P40: 1
A41: 1 | C41: =C40+1 -> 45745 | D41: =CHOOSE(WEEKDAY(C41,2),'Não Apagar'!$C$3,'Não Apagar'!$C$4,'Não Apagar'!$C$5,'Não Apagar'!$C$6,'Não Apagar'!$C$7,'Não Apagar'!$C$8,'Não Apagar'!$C$9) -> Sábado | P41: 1
...

Sheet Abr.25
A1: 1 | B1: 1 | C1: 1 | D1: 1 | E1: 1 | F1: 1 | G1: 1 | H1: 1 | I1: 1 | J1: 1 | K1: 1 | L1: 1 | M1: 1 | N1: 1 | O1: 1 | P1: 1
C3: Bluzz Saúde Ltda.
A4: 1 | C4: CNPJ | D4: 54.557.861/0001-02 | P4: 1
A5: 1 | C5: Colaborador | P5: 1
A6: 1 | C6: Mês Competência | D6: Abr.25 | P6: 1
A7: 1 | P7: 1
A8: 1 | P8: 1
A9: 1 | P9: 1
A10: 1 | P10: 1
A11: 1 | C11: CONTROLE DE PONTO | P11: 1
A12: 1 | C12: Data | D12: Dia da semana | E12: Entrada | F12: Saída Almoço | G12: Retorno Almoço | H12: Saída | I12: Horas Trabalhadas | J12: Horas Normais | K12: Horas Extras | L12: Banco de Horas | P12: 1
A13: 1 | C13: =Mar.25!C43 -> 45747 | D13: =Mar.25!D43 -> Segunda-feira | P13: 1
A14: 1 | C14: 45748 | D14: =CHOOSE(WEEKDAY(C14,2),'Não Apagar'!$C$3,'Não Apagar'!$C$4,'Não Apagar'!$C$5,'Não Apagar'!$C$6,'Não Apagar'!$C$7,'Não Apagar'!$C$8,'Não Apagar'!$C$9) -> Terça-feira | I14: =((H14-E14)-(G14-F14))*24 -> 0 | J14: =MAX(0,MIN(I14,'Não Apagar'!$J$3)) -> 0 | K14: =MAX(0,I14-'Não Apagar'!$J$3) -> 0 | L14: =K14+Mar.25!L45 -> 0 | P14: 1
A15: 1 | C15: =C14+1 -> 45749 | D15: =CHOOSE(WEEKDAY(C15,2),'Não Apagar'!$C$3,'Não Apagar'!$C$4,'Não Apagar'!$C$5,'Não Apagar'!$C$6,'Não Apagar'!$C$7,'Não Apagar'!$C$8,'Não Apagar'!$C$9) -> Quarta-feira | I15: =((H15-E15)-(G15-F15))*24 -> 0 | J15: =MAX(0,MIN(I15,'Não Apagar'!$J$3)) -> 0 | K15: =MAX(0,I15-'Não Apagar'!$J$3) -> 0 | L15: =L14+K15 -> 0 | P15: 1
A16: 1 | C16: =C15+1 -> 45750 | D16: =CHOOSE(WEEKDAY(C16,2),'Não Apagar'!$C$3,'Não Apagar'!$C$4,'Não Apagar'!$C$5,'Não Apagar'!$C$6,'Não Apagar'!$C$7,'Não Apagar'!$C$8,'Não Apagar'!$C$9) -> Segunda-feira | I16: =((H16-E16)-(G16-F16))*24 -> 0 | J16: =MAX(0,MIN(I16,'Não Apagar'!$J$3)) -> 0 | K16: =MAX(0,I16-'Não Apagar'!$J$3) -> 0 | L16: =L15+K16 -> 0 | P16: 1
A17: 1 | C17: =C16+1 -> 45751 | D17: =CHOOSE(WEEKDAY(C17,2),'Não Apagar'!$C$3,'Não Apagar'!$C$4,'Não Apagar'!$C$5,'Não Apagar'!$C$6,'Não Apagar'!$C$7,'Não Apagar'!$C$8,'Não Apagar'!$C$9) -> Sexta-feira | I17: =((H17-E17)-(G17-F17))*24 -> 0 | J17: =MAX(0,MIN(I17,'Não Apagar'!$J$3)) -> 0 | K17: =MAX(0,I17-'Não Apagar'!$J$3) -> 0 | L17: =L16+K17 -> 0 | P17: 1
A18: 1 | C18: =C17+1 -> 45752 | D18: =CHOOSE(WEEKDAY(C18,2),'Não Apagar'!$C$3,'Não Apagar'!$C$4,'Não Apagar'!$C$5,'Não Apagar'!$C$6,'Não Apagar'!$C$7,'Não Apagar'!$C$8,'Não Apagar'!$C$9) -> Sábado | P18: 1
A19: 1 | C19: =C18+1 -> 45753 | D19: =CHOOSE(WEEKDAY(C19,2),'Não Apagar'!$C$3,'Não Apagar'!$C$4,'Não Apagar'!$C$5,'Não Apagar'!$C$6,'Não Apagar'!$C$7,'Não Apagar'!$C$8,'Não Apagar'!$C$9) -> Domingo | P19: 1
A20: 1 | C20: =C19+1 -> 45754 | D20: =CHOOSE(WEEKDAY(C20,2),'Não Apagar'!$C$3,'Não Apagar'!$C$4,'Não Apagar'!$C$5,'Não Apagar'!$C$6,'Não Apagar'!$C$7,'Não Apagar'!$C$8,'Não Apagar'!$C$9) -> Segunda-feira | I20: =((H20-E20)-(G20-F20))*24 -> 0 | J20: =MAX(0,MIN(I20,'Não Apagar'!$J$3)) -> 0 | K20: =MAX(0,I20-'Não Apagar'!$J$3) -> 0 | L20: =L17+K20 -> 0 | P20: 1
A21: 1 | C21: =C20+1 -> 45755 | D21: =CHOOSE(WEEKDAY(C21,2),'Não Apagar'!$C$3,'Não Apagar'!$C$4,'Não Apagar'!$C$5,'Não Apagar'!$C$6,'Não Apagar'!$C$7,'Não Apagar'!$C$8,'Não Apagar'!$C$9) -> Terça-feira | I21: =((H21-E21)-(G21-F21))*24 -> 0 | J21: =MAX(0,MIN(I21,'Não Apagar'!$J$3)) -> 0 | K21: =MAX(0,I21-'Não Apagar'!$J$3) -> 0 | L21: =L20+K21 -> 0 | P21: 1
A22: 1 | C22: =C21+1 -> 45756 | D22: =CHOOSE(WEEKDAY(C22,2),'Não Apagar'!$C$3,'Não Apagar'!$C$4,'Não Apagar'!$C$5,'Não Apagar'!$C$6,'Não Apagar'!$C$7,'Não Apagar'!$C$8,'Não Apagar'!$C$9) -> Quarta-feira | I22: =((H22-E22)-(G22-F22))*24 -> 0 | J22: =MAX(0,MIN(I22,'Não Apagar'!$J$3)) -> 0 | K22: =MAX(0,I22-'Não Apagar'!$J$3) -> 0 | L22: =L21+K22 -> 0 | P22: 1
A23: 1 | C23: =C22+1 -> 45757 | D23: =CHOOSE(WEEKDAY(C23,2),'Não Apagar'!$C$3,'Não Apagar'!$C$4,'Não Apagar'!$C$5,'Não Apagar'!$C$6,'Não Apagar'!$C$7,'Não Apagar'!$C$8,'Não Apagar'!$C$9) -> Segunda-feira | I23: =((H23-E23)-(G23-F23))*24 -> 0 | J23: =MAX(0,MIN(I23,'Não Apagar'!$J$3)) -> 0 | K23: =MAX(0,I23-'Não Apagar'!$J$3) -> 0 | L23: =L22+K23 -> 0 | P23: 1
A24: 1 | C24: =C23+1 -> 45758 | D24: =CHOOSE(WEEKDAY(C24,2),'Não Apagar'!$C$3,'Não Apagar'!$C$4,'Não Apagar'!$C$5,'Não Apagar'!$C$6,'Não Apagar'!$C$7,'Não Apagar'!$C$8,'Não Apagar'!$C$9) -> Sexta-feira | I24: =((H24-E24)-(G24-F24))*24 -> 0 | J24: =MAX(0,MIN(I24,'Não Apagar'!$J$3)) -> 0 | K24: =MAX(0,I24-'Não Apagar'!$J$3) -> 0 | L24: =L23+K24 -> 0 | P24: 1
A25: 1 | C25: =C24+1 -> 45759 | D25: =CHOOSE(WEEKDAY(C25,2),'Não Apagar'!$C$3,'Não Apagar'!$C$4,'Não Apagar'!$C$5,'Não Apagar'!$C$6,'Não Apagar'!$C$7,'Não Apagar'!$C$8,'Não Apagar'!$C$9) -> Sábado | P25: 1
A26: 1 | C26: =C25+1 -> 45760 | D26: =CHOOSE(WEEKDAY(C26,2),'Não Apagar'!$C$3,'Não Apagar'!$C$4,'Não Apagar'!$C$5,'Não Apagar'!$C$6,'Não Apagar'!$C$7,'Não Apagar'!$C$8,'Não Apagar'!$C$9) -> Domingo | P26: 1
A27: 1 | C27: =C26+1 -> 45761 | D27: =CHOOSE(WEEKDAY(C27,2),'Não Apagar'!$C$3,'Não Apagar'!$C$4,'Não Apagar'!$C$5,'Não Apagar'!$C$6,'Não Apagar'!$C$7,'Não Apagar'!$C$8,'Não Apagar'!$C$9) -> Segunda-feira | I27: =((H27-E27)-(G27-F27))*24 -> 0 | J27: =MAX(0,MIN(I27,'Não Apagar'!$J$3)) -> 0 | K27: =MAX(0,I27-'Não Apagar'!$J$3) -> 0 | L27: =L24+K27 -> 0 | P27: 1
A28: 1 | C28: =C27+1 -> 45762 | D28: =CHOOSE(WEEKDAY(C28,2),'Não Apagar'!$C$3,'Não Apagar'!$C$4,'Não Apagar'!$C$5,'Não Apagar'!$C$6,'Não Apagar'!$C$7,'Não Apagar'!$C$8,'Não Apagar'!$C$9) -> Terça-feira | I28: =((H28-E28)-(G28-F28))*24 -> 0 | J28: =MAX(0,MIN(I28,'Não Apagar'!$J$3)) -> 0 | K28: =MAX(0,I28-'Não Apagar'!$J$3) -> 0 | L28: =L27+K28 -> 0 | P28: 1
A29: 1 | C29: =C28+1 -> 45763 | D29: =CHOOSE(WEEKDAY(C29,2),'Não Apagar'!$C$3,'Não Apagar'!$C$4,'Não Apagar'!$C$5,'Não Apagar'!$C$6,'Não Apagar'!$C$7,'Não Apagar'!$C$8,'Não Apagar'!$C$9) -> Quarta-feira | I29: =((H29-E29)-(G29-F29))*24 -> 0 | J29: =MAX(0,MIN(I29,'Não Apagar'!$J$3)) -> 0 | K29: =MAX(0,I29-'Não Apagar'!$J$3) -> 0 | L29: =L28+K29 -> 0 | P29: 1
A30: 1 | C30: =C29+1 -> 45764 | D30: =CHOOSE(WEEKDAY(C30,2),'Não Apagar'!$C$3,'Não Apagar'!$C$4,'Não Apagar'!$C$5,'Não Apagar'!$C$6,'Não Apagar'!$C$7,'Não Apagar'!$C$8,'Não Apagar'!$C$9) -> Segunda-feira | I30: =((H30-E30)-(G30-F30))*24 -> 0 | J30: =MAX(0,MIN(I30,'Não Apagar'!$J$3)) -> 0 | K30: =MAX(0,I30-'Não Apagar'!$J$3) -> 0 | L30: =L29+K30 -> 0 | P30: 1
A31: 1 | C31: =C30+1 -> 45765 | D31: =CHOOSE(WEEKDAY(C31,2),'Não Apagar'!$C$3,'Não Apagar'!$C$4,'Não Apagar'!$C$5,'Não Apagar'!$C$6,'Não Apagar'!$C$7,'Não Apagar'!$C$8,'Não Apagar'!$C$9) -> Sexta-feira | I31: =((H31-E31)-(G31-F31))*24 -> 0 | J31: =MAX(0,MIN(I31,'Não Apagar'!$J$3)) -> 0 | K31: =MAX(0,I31-'Não Apagar'!$J$3) -> 0 | L31: =L30+K31 -> 0 | P31: 1
A32: 1 | C32: =C31+1 -> 45766 | D32: =CHOOSE(WEEKDAY(C32,2),'Não Apagar'!$C$3,'Não Apagar'!$C$4,'Não Apagar'!$C$5,'Não Apagar'!$C$6,'Não Apagar'!$C$7,'Não Apagar'!$C$8,'Não Apagar'!$C$9) -> Sábado | P32: 1
A33: 1 | C33: =C32+1 -> 45767 | D33: =CHOOSE(WEEKDAY(C33,2),'Não Apagar'!$C$3,'Não Apagar'!$C$4,'Não Apagar'!$C$5,'Não Apagar'!$C$6,'Não Apagar'!$C$7,'Não Apagar'!$C$8,'Não Apagar'!$C$9) -> Domingo | P33: 1
A34: 1 | C34: =C33+1 -> 45768 | D34: =CHOOSE(WEEKDAY(C34,2),'Não Apagar'!$C$3,'Não Apagar'!$C$4,'Não Apagar'!$C$5,'Não Apagar'!$C$6,'Não Apagar'!$C$7,'Não Apagar'!$C$8,'Não Apagar'!$C$9) -> Segunda-feira | I34: =((H34-E34)-(G34-F34))*24 -> 0 | J34: =MAX(0,MIN(I34,'Não Apagar'!$J$3)) -> 0 | K34: =MAX(0,I34-'Não Apagar'!$J$3) -> 0 | L34: =L31+K34 -> 0 | P34: 1
A35: 1 | C35: =C34+1 -> 45769 | D35: =CHOOSE(WEEKDAY(C35,2),'Não Apagar'!$C$3,'Não Apagar'!$C$4,'Não Apagar'!$C$5,'Não Apagar'!$C$6,'Não Apagar'!$C$7,'Não Apagar'!$C$8,'Não Apagar'!$C$9) -> Terça-feira | I35: =((H35-E35)-(G35-F35))*24 -> 0 | J35: =MAX(0,MIN(I35,'Não Apagar'!$J$3)) -> 0 | K35: =MAX(0,I35-'Não Apagar'!$J$3) -> 0 | L35: =L34+K35 -> 0 | P35: 1
A36: 1 | C36: =C35+1 -> 45770 | D36: =CHOOSE(WEEKDAY(C36,2),'Não Apagar'!$C$3,'Não Apagar'!$C$4,'Não Apagar'!$C$5,'Não Apagar'!$C$6,'Não Apagar'!$C$7,'Não Apagar'!$C$8,'Não Apagar'!$C$9) -> Quarta-feira | I36: =((H36-E36)-(G36-F36))*24 -> 0 | J36: =MAX(0,MIN(I36,'Não Apagar'!$J$3)) -> 0 | K36: =MAX(0,I36-'Não Apagar'!$J$3) -> 0 | L36: =L35+K36 -> 0 | P36: 1
A37: 1 | C37: =C36+1 -> 45771 | D37: =CHOOSE(WEEKDAY(C37,2),'Não Apagar'!$C$3,'Não Apagar'!$C$4,'Não Apagar'!$C$5,'Não Apagar'!$C$6,'Não Apagar'!$C$7,'Não Apagar'!$C$8,'Não Apagar'!$C$9) -> Segunda-feira | I37: =((H37-E37)-(G37-F37))*24 -> 0 | J37: =MAX(0,MIN(I37,'Não Apagar'!$J$3)) -> 0 | K37: =MAX(0,I37-'Não Apagar'!$J$3) -> 0 | L37: =L36+K37 -> 0 | P37: 1
A38: 1 | C38: =C37+1 -> 45772 | D38: =CHOOSE(WEEKDAY(C38,2),'Não Apagar'!$C$3,'Não Apagar'!$C$4,'Não Apagar'!$C$5,'Não Apagar'!$C$6,'Não Apagar'!$C$7,'Não Apagar'!$C$8,'Não Apagar'!$C$9) -> Sexta-feira | I38: =((H38-E38)-(G38-F38))*24 -> 0 | J38: =MAX(0,MIN(I38,'Não Apagar'!$J$3)) -> 0 | K38: =MAX(0,I38-'Não Apagar'!$J$3) -> 0 | L38: =L37+K38 -> 0 | P38: 1
A39: 1 | C39: =C38+1 -> 45773 | D39: =CHOOSE(WEEKDAY(C39,2),'Não Apagar'!$C$3,'Não Apagar'!$C$4,'Não Apagar'!$C$5,'Não Apagar'!$C$6,'Não Apagar'!$C$7,'Não Apagar'!$C$8,'Não Apagar'!$C$9) -> Sábado | P39: 1
A40: 1 | C40: =C39+1 -> 45774 | D40: =CHOOSE(WEEKDAY(C40,2),'Não Apagar'!$C$3,'Não Apagar'!$C$4,'Não Apagar'!$C$5,'Não Apagar'!$C$6,'Não Apagar'!$C$7,'Não Apagar'!$C$8,'Não Apagar'!$C$9) -> Domingo | P40: 1
A41: 1 | C41: =C40+1 -> 45775 | D41: =CHOOSE(WEEKDAY(C41,2),'Não Apagar'!$C$3,'Não Apagar'!$C$4,'Não Apagar'!$C$5,'Não Apagar'!$C$6,'Não Apagar'!$C$7,'Não Apagar'!$C$8,'Não Apagar'!$C$9) -> Segunda-feira | I41: =((H41-E41)-(G41-F41))*24 -> 0 | J41: =MAX(0,MIN(I41,'Não Apagar'!$J$3)) -> 0 | K41: =MAX(0,I41-'Não Apagar'!$J$3) -> 0 | L41: =L38+K41 -> 0 | P41: 1
...

Sheet Mai.25
A1: 1 | B1: 1 | C1: 1 | D1: 1 | E1: 1 | F1: 1 | G1: 1 | H1: 1 | I1: 1 | J1: 1 | K1: 1 | L1: 1 | M1: 1 | N1: 1 | O1: 1 | P1: 1
C3: Bluzz Saúde Ltda.
A4: 1 | C4: CNPJ | D4: 54.557.861/0001-02 | P4: 1
A5: 1 | C5: Colaborador | P5: 1
A6: 1 | C6: Mês Competência | D6: Mai.25 | P6: 1
A7: 1 | P7: 1
A8: 1 | P8: 1
A9: 1 | P9: 1
A10: 1 | P10: 1
A11: 1 | C11: CONTROLE DE PONTO | P11: 1
A12: 1 | C12: Data | D12: Dia da semana | E12: Entrada | F12: Saída Almoço | G12: Retorno Almoço | H12: Saída | I12: Horas Trabalhadas | J12: Horas Normais | K12: Horas Extras | L12: Banco de Horas | P12: 1
A13: 1 | P13: 1
A14: 1 | C14: 45778 | D14: =CHOOSE(WEEKDAY(C14,2),'Não Apagar'!$C$3,'Não Apagar'!$C$4,'Não Apagar'!$C$5,'Não Apagar'!$C$6,'Não Apagar'!$C$7,'Não Apagar'!$C$8,'Não Apagar'!$C$9) -> Segunda-feira | I14: =((H14-E14)-(G14-F14))*24 -> 0 | J14: =MAX(0,MIN(I14,'Não Apagar'!$J$3)) -> 0 | K14: =MAX(0,I14-'Não Apagar'!$J$3) -> 0 | L14: =K14+Abr.25!L46 -> 0 | P14: 1
A15: 1 | C15: =C14+1 -> 45779 | D15: =CHOOSE(WEEKDAY(C15,2),'Não Apagar'!$C$3,'Não Apagar'!$C$4,'Não Apagar'!$C$5,'Não Apagar'!$C$6,'Não Apagar'!$C$7,'Não Apagar'!$C$8,'Não Apagar'!$C$9) -> Sexta-feira | I15: =((H15-E15)-(G15-F15))*24 -> 0 | J15: =MAX(0,MIN(I15,'Não Apagar'!$J$3)) -> 0 | K15: =MAX(0,I15-'Não Apagar'!$J$3) -> 0 | L15: =L14+K15 -> 0 | P15: 1
A16: 1 | C16: =C15+1 -> 45780 | D16: =CHOOSE(WEEKDAY(C16,2),'Não Apagar'!$C$3,'Não Apagar'!$C$4,'Não Apagar'!$C$5,'Não Apagar'!$C$6,'Não Apagar'!$C$7,'Não Apagar'!$C$8,'Não Apagar'!$C$9) -> Sábado | P16: 1
A17: 1 | C17: =C16+1 -> 45781 | D17: =CHOOSE(WEEKDAY(C17,2),'Não Apagar'!$C$3,'Não Apagar'!$C$4,'Não Apagar'!$C$5,'Não Apagar'!$C$6,'Não Apagar'!$C$7,'Não Apagar'!$C$8,'Não Apagar'!$C$9) -> Domingo | P17: 1
A18: 1 | C18: =C17+1 -> 45782 | D18: =CHOOSE(WEEKDAY(C18,2),'Não Apagar'!$C$3,'Não Apagar'!$C$4,'Não Apagar'!$C$5,'Não Apagar'!$C$6,'Não Apagar'!$C$7,'Não Apagar'!$C$8,'Não Apagar'!$C$9) -> Segunda-feira | I18: =((H18-E18)-(G18-F18))*24 -> 0 | J18: =MAX(0,MIN(I18,'Não Apagar'!$J$3)) -> 0 | K18: =MAX(0,I18-'Não Apagar'!$J$3) -> 0 | L18: =L15+K18 -> 0 | P18: 1
A19: 1 | C19: =C18+1 -> 45783 | D19: =CHOOSE(WEEKDAY(C19,2),'Não Apagar'!$C$3,'Não Apagar'!$C$4,'Não Apagar'!$C$5,'Não Apagar'!$C$6,'Não Apagar'!$C$7,'Não Apagar'!$C$8,'Não Apagar'!$C$9) -> Terça-feira | I19: =((H19-E19)-(G19-F19))*24 -> 0 | J19: =MAX(0,MIN(I19,'Não Apagar'!$J$3)) -> 0 | K19: =MAX(0,I19-'Não Apagar'!$J$3) -> 0 | L19: =L18+K19 -> 0 | P19: 1
A20: 1 | C20: =C19+1 -> 45784 | D20: =CHOOSE(WEEKDAY(C20,2),'Não Apagar'!$C$3,'Não Apagar'!$C$4,'Não Apagar'!$C$5,'Não Apagar'!$C$6,'Não Apagar'!$C$7,'Não Apagar'!$C$8,'Não Apagar'!$C$9) -> Quarta-feira | I20: =((H20-E20)-(G20-F20))*24 -> 0 | J20: =MAX(0,MIN(I20,'Não Apagar'!$J$3)) -> 0 | K20: =MAX(0,I20-'Não Apagar'!$J$3) -> 0 | L20: =L19+K20 -> 0 | P20: 1
A21: 1 | C21: =C20+1 -> 45785 | D21: =CHOOSE(WEEKDAY(C21,2),'Não Apagar'!$C$3,'Não Apagar'!$C$4,'Não Apagar'!$C$5,'Não Apagar'!$C$6,'Não Apagar'!$C$7,'Não Apagar'!$C$8,'Não Apagar'!$C$9) -> Segunda-feira | I21: =((H21-E21)-(G21-F21))*24 -> 0 | J21: =MAX(0,MIN(I21,'Não Apagar'!$J$3)) -> 0 | K21: =MAX(0,I21-'Não Apagar'!$J$3) -> 0 | L21: =L20+K21 -> 0 | P21: 1
A22: 1 | C22: =C21+1 -> 45786 | D22: =CHOOSE(WEEKDAY(C22,2),'Não Apagar'!$C$3,'Não Apagar'!$C$4,'Não Apagar'!$C$5,'Não Apagar'!$C$6,'Não Apagar'!$C$7,'Não Apagar'!$C$8,'Não Apagar'!$C$9) -> Sexta-feira | I22: =((H22-E22)-(G22-F22))*24 -> 0 | J22: =MAX(0,MIN(I22,'Não Apagar'!$J$3)) -> 0 | K22: =MAX(0,I22-'Não Apagar'!$J$3) -> 0 | L22: =L21+K22 -> 0 | P22: 1
A23: 1 | C23: =C22+1 -> 45787 | D23: =CHOOSE(WEEKDAY(C23,2),'Não Apagar'!$C$3,'Não Apagar'!$C$4,'Não Apagar'!$C$5,'Não Apagar'!$C$6,'Não Apagar'!$C$7,'Não Apagar'!$C$8,'Não Apagar'!$C$9) -> Sábado | P23: 1
A24: 1 | C24: =C23+1 -> 45788 | D24: =CHOOSE(WEEKDAY(C24,2),'Não Apagar'!$C$3,'Não Apagar'!$C$4,'Não Apagar'!$C$5,'Não Apagar'!$C$6,'Não Apagar'!$C$7,'Não Apagar'!$C$8,'Não Apagar'!$C$9) -> Domingo | P24: 1
A25: 1 | C25: =C24+1 -> 45789 | D25: =CHOOSE(WEEKDAY(C25,2),'Não Apagar'!$C$3,'Não Apagar'!$C$4,'Não Apagar'!$C$5,'Não Apagar'!$C$6,'Não Apagar'!$C$7,'Não Apagar'!$C$8,'Não Apagar'!$C$9) -> Segunda-feira | I25: =((H25-E25)-(G25-F25))*24 -> 0 | J25: =MAX(0,MIN(I25,'Não Apagar'!$J$3)) -> 0 | K25: =MAX(0,I25-'Não Apagar'!$J$3) -> 0 | L25: =L22+K25 -> 0 | P25: 1
A26: 1 | C26: =C25+1 -> 45790 | D26: =CHOOSE(WEEKDAY(C26,2),'Não Apagar'!$C$3,'Não Apagar'!$C$4,'Não Apagar'!$C$5,'Não Apagar'!$C$6,'Não Apagar'!$C$7,'Não Apagar'!$C$8,'Não Apagar'!$C$9) -> Terça-feira | I26: =((H26-E26)-(G26-F26))*24 -> 0 | J26: =MAX(0,MIN(I26,'Não Apagar'!$J$3)) -> 0 | K26: =MAX(0,I26-'Não Apagar'!$J$3) -> 0 | L26: =L25+K26 -> 0 | P26: 1
A27: 1 | C27: =C26+1 -> 45791 | D27: =CHOOSE(WEEKDAY(C27,2),'Não Apagar'!$C$3,'Não Apagar'!$C$4,'Não Apagar'!$C$5,'Não Apagar'!$C$6,'Não Apagar'!$C$7,'Não Apagar'!$C$8,'Não Apagar'!$C$9) -> Quarta-feira | I27: =((H27-E27)-(G27-F27))*24 -> 0 | J27: =MAX(0,MIN(I27,'Não Apagar'!$J$3)) -> 0 | K27: =MAX(0,I27-'Não Apagar'!$J$3) -> 0 | L27: =L26+K27 -> 0 | P27: 1
A28: 1 | C28: =C27+1 -> 45792 | D28: =CHOOSE(WEEKDAY(C28,2),'Não Apagar'!$C$3,'Não Apagar'!$C$4,'Não Apagar'!$C$5,'Não Apagar'!$C$6,'Não Apagar'!$C$7,'Não Apagar'!$C$8,'Não Apagar'!$C$9) -> Segunda-feira | I28: =((H28-E28)-(G28-F28))*24 -> 0 | J28: =MAX(0,MIN(I28,'Não Apagar'!$J$3)) -> 0 | K28: =MAX(0,I28-'Não Apagar'!$J$3) -> 0 | L28: =L27+K28 -> 0 | P28: 1
A29: 1 | C29: =C28+1 -> 45793 | D29: =CHOOSE(WEEKDAY(C29,2),'Não Apagar'!$C$3,'Não Apagar'!$C$4,'Não Apagar'!$C$5,'Não Apagar'!$C$6,'Não Apagar'!$C$7,'Não Apagar'!$C$8,'Não Apagar'!$C$9) -> Sexta-feira | I29: =((H29-E29)-(G29-F29))*24 -> 0 | J29: =MAX(0,MIN(I29,'Não Apagar'!$J$3)) -> 0 | K29: =MAX(0,I29-'Não Apagar'!$J$3) -> 0 | L29: =L28+K29 -> 0 | P29: 1
A30: 1 | C30: =C29+1 -> 45794 | D30: =CHOOSE(WEEKDAY(C30,2),'Não Apagar'!$C$3,'Não Apagar'!$C$4,'Não Apagar'!$C$5,'Não Apagar'!$C$6,'Não Apagar'!$C$7,'Não Apagar'!$C$8,'Não Apagar'!$C$9) -> Sábado | P30: 1
A31: 1 | C31: =C30+1 -> 45795 | D31: =CHOOSE(WEEKDAY(C31,2),'Não Apagar'!$C$3,'Não Apagar'!$C$4,'Não Apagar'!$C$5,'Não Apagar'!$C$6,'Não Apagar'!$C$7,'Não Apagar'!$C$8,'Não Apagar'!$C$9) -> Domingo | P31: 1
A32: 1 | C32: =C31+1 -> 45796 | D32: =CHOOSE(WEEKDAY(C32,2),'Não Apagar'!$C$3,'Não Apagar'!$C$4,'Não Apagar'!$C$5,'Não Apagar'!$C$6,'Não Apagar'!$C$7,'Não Apagar'!$C$8,'Não Apagar'!$C$9) -> Segunda-feira | I32: =((H32-E32)-(G32-F32))*24 -> 0 | J32: =MAX(0,MIN(I32,'Não Apagar'!$J$3)) -> 0 | K32: =MAX(0,I32-'Não Apagar'!$J$3) -> 0 | L32: =L29+K32 -> 0 | P32: 1
A33: 1 | C33: =C32+1 -> 45797 | D33: =CHOOSE(WEEKDAY(C33,2),'Não Apagar'!$C$3,'Não Apagar'!$C$4,'Não Apagar'!$C$5,'Não Apagar'!$C$6,'Não Apagar'!$C$7,'Não Apagar'!$C$8,'Não Apagar'!$C$9) -> Terça-feira | I33: =((H33-E33)-(G33-F33))*24 -> 0 | J33: =MAX(0,MIN(I33,'Não Apagar'!$J$3)) -> 0 | K33: =MAX(0,I33-'Não Apagar'!$J$3) -> 0 | L33: =L32+K33 -> 0 | P33: 1
A34: 1 | C34: =C33+1 -> 45798 | D34: =CHOOSE(WEEKDAY(C34,2),'Não Apagar'!$C$3,'Não Apagar'!$C$4,'Não Apagar'!$C$5,'Não Apagar'!$C$6,'Não Apagar'!$C$7,'Não Apagar'!$C$8,'Não Apagar'!$C$9) -> Quarta-feira | I34: =((H34-E34)-(G34-F34))*24 -> 0 | J34: =MAX(0,MIN(I34,'Não Apagar'!$J$3)) -> 0 | K34: =MAX(0,I34-'Não Apagar'!$J$3) -> 0 | L34: =L33+K34 -> 0 | P34: 1
A35: 1 | C35: =C34+1 -> 45799 | D35: =CHOOSE(WEEKDAY(C35,2),'Não Apagar'!$C$3,'Não Apagar'!$C$4,'Não Apagar'!$C$5,'Não Apagar'!$C$6,'Não Apagar'!$C$7,'Não Apagar'!$C$8,'Não Apagar'!$C$9) -> Segunda-feira | I35: =((H35-E35)-(G35-F35))*24 -> 0 | J35: =MAX(0,MIN(I35,'Não Apagar'!$J$3)) -> 0 | K35: =MAX(0,I35-'Não Apagar'!$J$3) -> 0 | L35: =L34+K35 -> 0 | P35: 1
A36: 1 | C36: =C35+1 -> 45800 | D36: =CHOOSE(WEEKDAY(C36,2),'Não Apagar'!$C$3,'Não Apagar'!$C$4,'Não Apagar'!$C$5,'Não Apagar'!$C$6,'Não Apagar'!$C$7,'Não Apagar'!$C$8,'Não Apagar'!$C$9) -> Sexta-feira | I36: =((H36-E36)-(G36-F36))*24 -> 0 | J36: =MAX(0,MIN(I36,'Não Apagar'!$J$3)) -> 0 | K36: =MAX(0,I36-'Não Apagar'!$J$3) -> 0 | L36: =L35+K36 -> 0 | P36: 1
A37: 1 | C37: =C36+1 -> 45801 | D37: =CHOOSE(WEEKDAY(C37,2),'Não Apagar'!$C$3,'Não Apagar'!$C$4,'Não Apagar'!$C$5,'Não Apagar'!$C$6,'Não Apagar'!$C$7,'Não Apagar'!$C$8,'Não Apagar'!$C$9) -> Sábado | P37: 1
A38: 1 | C38: =C37+1 -> 45802 | D38: =CHOOSE(WEEKDAY(C38,2),'Não Apagar'!$C$3,'Não Apagar'!$C$4,'Não Apagar'!$C$5,'Não Apagar'!$C$6,'Não Apagar'!$C$7,'Não Apagar'!$C$8,'Não Apagar'!$C$9) -> Domingo | P38: 1
A39: 1 | C39: =C38+1 -> 45803 | D39: =CHOOSE(WEEKDAY(C39,2),'Não Apagar'!$C$3,'Não Apagar'!$C$4,'Não Apagar'!$C$5,'Não Apagar'!$C$6,'Não Apagar'!$C$7,'Não Apagar'!$C$8,'Não Apagar'!$C$9) -> Segunda-feira | I39: =((H39-E39)-(G39-F39))*24 -> 0 | J39: =MAX(0,MIN(I39,'Não Apagar'!$J$3)) -> 0 | K39: =MAX(0,I39-'Não Apagar'!$J$3) -> 0 | L39: =L36+K39 -> 0 | P39: 1
A40: 1 | C40: =C39+1 -> 45804 | D40: =CHOOSE(WEEKDAY(C40,2),'Não Apagar'!$C$3,'Não Apagar'!$C$4,'Não Apagar'!$C$5,'Não Apagar'!$C$6,'Não Apagar'!$C$7,'Não Apagar'!$C$8,'Não Apagar'!$C$9) -> Terça-feira | I40: =((H40-E40)-(G40-F40))*24 -> 0 | J40: =MAX(0,MIN(I40,'Não Apagar'!$J$3)) -> 0 | K40: =MAX(0,I40-'Não Apagar'!$J$3) -> 0 | L40: =L39+K40 -> 0 | P40: 1
A41: 1 | C41: =C40+1 -> 45805 | D41: =CHOOSE(WEEKDAY(C41,2),'Não Apagar'!$C$3,'Não Apagar'!$C$4,'Não Apagar'!$C$5,'Não Apagar'!$C$6,'Não Apagar'!$C$7,'Não Apagar'!$C$8,'Não Apagar'!$C$9) -> Quarta-feira | I41: =((H41-E41)-(G41-F41))*24 -> 0 | J41: =MAX(0,MIN(I41,'Não Apagar'!$J$3)) -> 0 | K41: =MAX(0,I41-'Não Apagar'!$J$3) -> 0 | L41: =L40+K41 -> 0 | P41: 1
...

Sheet Jun.25
A1: 1 | B1: 1 | C1: 1 | D1: 1 | E1: 1 | F1: 1 | G1: 1 | H1: 1 | I1: 1 | J1: 1 | K1: 1 | L1: 1 | M1: 1 | N1: 1 | O1: 1 | P1: 1
C3: Bluzz Saúde Ltda.
A4: 1 | C4: CNPJ | D4: 54.557.861/0001-02 | P4: 1
A5: 1 | C5: Colaborador | P5: 1
A6: 1 | C6: Mês Competência | D6: Jun.25 | P6: 1
A7: 1 | P7: 1
A8: 1 | P8: 1
A9: 1 | P9: 1
A10: 1 | P10: 1
A11: 1 | C11: CONTROLE DE PONTO | P11: 1
A12: 1 | C12: Data | D12: Dia da semana | E12: Entrada | F12: Saída Almoço | G12: Retorno Almoço | H12: Saída | I12: Horas Trabalhadas | J12: Horas Normais | K12: Horas Extras | L12: Banco de Horas | P12: 1
A13: 1 | C13: 45809 | D13: =CHOOSE(WEEKDAY(C13,2),'Não Apagar'!$C$3,'Não Apagar'!$C$4,'Não Apagar'!$C$5,'Não Apagar'!$C$6,'Não Apagar'!$C$7,'Não Apagar'!$C$8,'Não Apagar'!$C$9) -> Domingo | P13: 1
A14: 1 | C14: =C13+1 -> 45810 | D14: =CHOOSE(WEEKDAY(C14,2),'Não Apagar'!$C$3,'Não Apagar'!$C$4,'Não Apagar'!$C$5,'Não Apagar'!$C$6,'Não Apagar'!$C$7,'Não Apagar'!$C$8,'Não Apagar'!$C$9) -> Segunda-feira | E14: 0 | F14: 0 | G14: 0 | H14: 0 | I14: =((H14-E14)-(G14-F14))*24 -> 0 | J14: =MAX(0,MIN(I14,'Não Apagar'!$J$3)) -> 0 | K14: =MAX(0,I14-'Não Apagar'!$J$3) -> 0 | L14: =K14+Mai.25!L46 -> 0 | P14: 1
A15: 1 | C15: =C14+1 -> 45811 | D15: =CHOOSE(WEEKDAY(C15,2),'Não Apagar'!$C$3,'Não Apagar'!$C$4,'Não Apagar'!$C$5,'Não Apagar'!$C$6,'Não Apagar'!$C$7,'Não Apagar'!$C$8,'Não Apagar'!$C$9) -> Terça-feira | E15: 0 | F15: 0 | G15: 0 | H15: 0 | I15: =((H15-E15)-(G15-F15))*24 -> 0 | J15: =MAX(0,MIN(I15,'Não Apagar'!$J$3)) -> 0 | K15: =MAX(0,I15-'Não Apagar'!$J$3) -> 0 | L15: =L14+K15 -> 0 | P15: 1
A16: 1 | C16: =C15+1 -> 45812 | D16: =CHOOSE(WEEKDAY(C16,2),'Não Apagar'!$C$3,'Não Apagar'!$C$4,'Não Apagar'!$C$5,'Não Apagar'!$C$6,'Não Apagar'!$C$7,'Não Apagar'!$C$8,'Não Apagar'!$C$9) -> Quarta-feira | E16: 0 | F16: 0 | G16: 0 | H16: 0 | I16: =((H16-E16)-(G16-F16))*24 -> 0 | J16: =MAX(0,MIN(I16,'Não Apagar'!$J$3)) -> 0 | K16: =MAX(0,I16-'Não Apagar'!$J$3) -> 0 | L16: =L15+K16 -> 0 | P16: 1
A17: 1 | C17: =C16+1 -> 45813 | D17: =CHOOSE(WEEKDAY(C17,2),'Não Apagar'!$C$3,'Não Apagar'!$C$4,'Não Apagar'!$C$5,'Não Apagar'!$C$6,'Não Apagar'!$C$7,'Não Apagar'!$C$8,'Não Apagar'!$C$9) -> Segunda-feira | E17: 0 | F17: 0 | G17: 0 | H17: 0 | I17: =((H17-E17)-(G17-F17))*24 -> 0 | J17: =MAX(0,MIN(I17,'Não Apagar'!$J$3)) -> 0 | K17: =MAX(0,I17-'Não Apagar'!$J$3) -> 0 | L17: =L16+K17 -> 0 | P17: 1
A18: 1 | C18: =C17+1 -> 45814 | D18: =CHOOSE(WEEKDAY(C18,2),'Não Apagar'!$C$3,'Não Apagar'!$C$4,'Não Apagar'!$C$5,'Não Apagar'!$C$6,'Não Apagar'!$C$7,'Não Apagar'!$C$8,'Não Apagar'!$C$9) -> Sexta-feira | E18: 0 | F18: 0 | G18: 0 | H18: 0 | I18: =((H18-E18)-(G18-F18))*24 -> 0 | J18: =MAX(0,MIN(I18,'Não Apagar'!$J$3)) -> 0 | K18: =MAX(0,I18-'Não Apagar'!$J$3) -> 0 | L18: =L17+K18 -> 0 | P18: 1
A19: 1 | C19: =C18+1 -> 45815 | D19: =CHOOSE(WEEKDAY(C19,2),'Não Apagar'!$C$3,'Não Apagar'!$C$4,'Não Apagar'!$C$5,'Não Apagar'!$C$6,'Não Apagar'!$C$7,'Não Apagar'!$C$8,'Não Apagar'!$C$9) -> Sábado | P19: 1
A20: 1 | C20: =C19+1 -> 45816 | D20: =CHOOSE(WEEKDAY(C20,2),'Não Apagar'!$C$3,'Não Apagar'!$C$4,'Não Apagar'!$C$5,'Não Apagar'!$C$6,'Não Apagar'!$C$7,'Não Apagar'!$C$8,'Não Apagar'!$C$9) -> Domingo | P20: 1
A21: 1 | C21: =C20+1 -> 45817 | D21: =CHOOSE(WEEKDAY(C21,2),'Não Apagar'!$C$3,'Não Apagar'!$C$4,'Não Apagar'!$C$5,'Não Apagar'!$C$6,'Não Apagar'!$C$7,'Não Apagar'!$C$8,'Não Apagar'!$C$9) -> Segunda-feira | E21: 0 | F21: 0 | G21: 0 | H21: 0 | I21: =((H21-E21)-(G21-F21))*24 -> 0 | J21: =MAX(0,MIN(I21,'Não Apagar'!$J$3)) -> 0 | K21: =MAX(0,I21-'Não Apagar'!$J$3) -> 0 | L21: =L18+K21 -> 0 | P21: 1
A22: 1 | C22: =C21+1 -> 45818 | D22: =CHOOSE(WEEKDAY(C22,2),'Não Apagar'!$C$3,'Não Apagar'!$C$4,'Não Apagar'!$C$5,'Não Apagar'!$C$6,'Não Apagar'!$C$7,'Não Apagar'!$C$8,'Não Apagar'!$C$9) -> Terça-feira | E22: 0 | F22: 0 | G22: 0 | H22: 0 | I22: =((H22-E22)-(G22-F22))*24 -> 0 | J22: =MAX(0,MIN(I22,'Não Apagar'!$J$3)) -> 0 | K22: =MAX(0,I22-'Não Apagar'!$J$3) -> 0 | L22: =L21+K22 -> 0 | P22: 1
A23: 1 | C23: =C22+1 -> 45819 | D23: =CHOOSE(WEEKDAY(C23,2),'Não Apagar'!$C$3,'Não Apagar'!$C$4,'Não Apagar'!$C$5,'Não Apagar'!$C$6,'Não Apagar'!$C$7,'Não Apagar'!$C$8,'Não Apagar'!$C$9) -> Quarta-feira | E23: 0 | F23: 0 | G23: 0 | H23: 0 | I23: =((H23-E23)-(G23-F23))*24 -> 0 | J23: =MAX(0,MIN(I23,'Não Apagar'!$J$3)) -> 0 | K23: =MAX(0,I23-'Não Apagar'!$J$3) -> 0 | L23: =L22+K23 -> 0 | P23: 1
A24: 1 | C24: =C23+1 -> 45820 | D24: =CHOOSE(WEEKDAY(C24,2),'Não Apagar'!$C$3,'Não Apagar'!$C$4,'Não Apagar'!$C$5,'Não Apagar'!$C$6,'Não Apagar'!$C$7,'Não Apagar'!$C$8,'Não Apagar'!$C$9) -> Segunda-feira | E24: 0 | F24: 0 | G24: 0 | H24: 0 | I24: =((H24-E24)-(G24-F24))*24 -> 0 | J24: =MAX(0,MIN(I24,'Não Apagar'!$J$3)) -> 0 | K24: =MAX(0,I24-'Não Apagar'!$J$3) -> 0 | L24: =L23+K24 -> 0 | P24: 1
A25: 1 | C25: =C24+1 -> 45821 | D25: =CHOOSE(WEEKDAY(C25,2),'Não Apagar'!$C$3,'Não Apagar'!$C$4,'Não Apagar'!$C$5,'Não Apagar'!$C$6,'Não Apagar'!$C$7,'Não Apagar'!$C$8,'Não Apagar'!$C$9) -> Sexta-feira | E25: 0 | F25: 0 | G25: 0 | H25: 0 | I25: =((H25-E25)-(G25-F25))*24 -> 0 | J25: =MAX(0,MIN(I25,'Não Apagar'!$J$3)) -> 0 | K25: =MAX(0,I25-'Não Apagar'!$J$3) -> 0 | L25: =L24+K25 -> 0 | P25: 1
A26: 1 | C26: =C25+1 -> 45822 | D26: =CHOOSE(WEEKDAY(C26,2),'Não Apagar'!$C$3,'Não Apagar'!$C$4,'Não Apagar'!$C$5,'Não Apagar'!$C$6,'Não Apagar'!$C$7,'Não Apagar'!$C$8,'Não Apagar'!$C$9) -> Sábado | P26: 1
A27: 1 | C27: =C26+1 -> 45823 | D27: =CHOOSE(WEEKDAY(C27,2),'Não Apagar'!$C$3,'Não Apagar'!$C$4,'Não Apagar'!$C$5,'Não Apagar'!$C$6,'Não Apagar'!$C$7,'Não Apagar'!$C$8,'Não Apagar'!$C$9) -> Domingo | P27: 1
A28: 1 | C28: =C27+1 -> 45824 | D28: =CHOOSE(WEEKDAY(C28,2),'Não Apagar'!$C$3,'Não Apagar'!$C$4,'Não Apagar'!$C$5,'Não Apagar'!$C$6,'Não Apagar'!$C$7,'Não Apagar'!$C$8,'Não Apagar'!$C$9) -> Segunda-feira | I28: =((H28-E28)-(G28-F28))*24 -> 0 | J28: =MAX(0,MIN(I28,'Não Apagar'!$J$3)) -> 0 | K28: =MAX(0,I28-'Não Apagar'!$J$3) -> 0 | L28: =L25+K28 -> 0 | P28: 1
A29: 1 | C29: =C28+1 -> 45825 | D29: =CHOOSE(WEEKDAY(C29,2),'Não Apagar'!$C$3,'Não Apagar'!$C$4,'Não Apagar'!$C$5,'Não Apagar'!$C$6,'Não Apagar'!$C$7,'Não Apagar'!$C$8,'Não Apagar'!$C$9) -> Terça-feira | I29: =((H29-E29)-(G29-F29))*24 -> 0 | J29: =MAX(0,MIN(I29,'Não Apagar'!$J$3)) -> 0 | K29: =MAX(0,I29-'Não Apagar'!$J$3) -> 0 | L29: =L28+K29 -> 0 | P29: 1
A30: 1 | C30: =C29+1 -> 45826 | D30: =CHOOSE(WEEKDAY(C30,2),'Não Apagar'!$C$3,'Não Apagar'!$C$4,'Não Apagar'!$C$5,'Não Apagar'!$C$6,'Não Apagar'!$C$7,'Não Apagar'!$C$8,'Não Apagar'!$C$9) -> Quarta-feira | I30: =((H30-E30)-(G30-F30))*24 -> 0 | J30: =MAX(0,MIN(I30,'Não Apagar'!$J$3)) -> 0 | K30: =MAX(0,I30-'Não Apagar'!$J$3) -> 0 | L30: =L29+K30 -> 0 | P30: 1
A31: 1 | C31: =C30+1 -> 45827 | D31: =CHOOSE(WEEKDAY(C31,2),'Não Apagar'!$C$3,'Não Apagar'!$C$4,'Não Apagar'!$C$5,'Não Apagar'!$C$6,'Não Apagar'!$C$7,'Não Apagar'!$C$8,'Não Apagar'!$C$9) -> Segunda-feira | I31: =((H31-E31)-(G31-F31))*24 -> 0 | J31: =MAX(0,MIN(I31,'Não Apagar'!$J$3)) -> 0 | K31: =MAX(0,I31-'Não Apagar'!$J$3) -> 0 | L31: =L30+K31 -> 0 | P31: 1
A32: 1 | C32: =C31+1 -> 45828 | D32: =CHOOSE(WEEKDAY(C32,2),'Não Apagar'!$C$3,'Não Apagar'!$C$4,'Não Apagar'!$C$5,'Não Apagar'!$C$6,'Não Apagar'!$C$7,'Não Apagar'!$C$8,'Não Apagar'!$C$9) -> Sexta-feira | E32: 0 | F32: 0 | G32: 0.53472222 | H32: 0.74652778 | I32: =((H32-E32)-(G32-F32))*24 -> 5.0833333 | J32: =MAX(0,MIN(I32,'Não Apagar'!$J$3)) -> 5.0833333 | K32: =MAX(0,I32-'Não Apagar'!$J$3) -> 0 | L32: =L31+K32 -> 0 | P32: 1
A33: 1 | C33: =C32+1 -> 45829 | D33: =CHOOSE(WEEKDAY(C33,2),'Não Apagar'!$C$3,'Não Apagar'!$C$4,'Não Apagar'!$C$5,'Não Apagar'!$C$6,'Não Apagar'!$C$7,'Não Apagar'!$C$8,'Não Apagar'!$C$9) -> Sábado | P33: 1
A34: 1 | C34: =C33+1 -> 45830 | D34: =CHOOSE(WEEKDAY(C34,2),'Não Apagar'!$C$3,'Não Apagar'!$C$4,'Não Apagar'!$C$5,'Não Apagar'!$C$6,'Não Apagar'!$C$7,'Não Apagar'!$C$8,'Não Apagar'!$C$9) -> Domingo | P34: 1
A35: 1 | C35: =C34+1 -> 45831 | D35: =CHOOSE(WEEKDAY(C35,2),'Não Apagar'!$C$3,'Não Apagar'!$C$4,'Não Apagar'!$C$5,'Não Apagar'!$C$6,'Não Apagar'!$C$7,'Não Apagar'!$C$8,'Não Apagar'!$C$9) -> Segunda-feira | I35: =((H35-E35)-(G35-F35))*24 -> 0 | J35: =MAX(0,MIN(I35,'Não Apagar'!$J$3)) -> 0 | K35: =MAX(0,I35-'Não Apagar'!$J$3) -> 0 | L35: =L32+K35 -> 0 | P35: 1
A36: 1 | C36: =C35+1 -> 45832 | D36: =CHOOSE(WEEKDAY(C36,2),'Não Apagar'!$C$3,'Não Apagar'!$C$4,'Não Apagar'!$C$5,'Não Apagar'!$C$6,'Não Apagar'!$C$7,'Não Apagar'!$C$8,'Não Apagar'!$C$9) -> Terça-feira | I36: =((H36-E36)-(G36-F36))*24 -> 0 | J36: =MAX(0,MIN(I36,'Não Apagar'!$J$3)) -> 0 | K36: =MAX(0,I36-'Não Apagar'!$J$3) -> 0 | L36: =L35+K36 -> 0 | P36: 1
A37: 1 | C37: =C36+1 -> 45833 | D37: =CHOOSE(WEEKDAY(C37,2),'Não Apagar'!$C$3,'Não Apagar'!$C$4,'Não Apagar'!$C$5,'Não Apagar'!$C$6,'Não Apagar'!$C$7,'Não Apagar'!$C$8,'Não Apagar'!$C$9) -> Quarta-feira | I37: =((H37-E37)-(G37-F37))*24 -> 0 | J37: =MAX(0,MIN(I37,'Não Apagar'!$J$3)) -> 0 | K37: =MAX(0,I37-'Não Apagar'!$J$3) -> 0 | L37: =L36+K37 -> 0 | P37: 1
A38: 1 | C38: =C37+1 -> 45834 | D38: =CHOOSE(WEEKDAY(C38,2),'Não Apagar'!$C$3,'Não Apagar'!$C$4,'Não Apagar'!$C$5,'Não Apagar'!$C$6,'Não Apagar'!$C$7,'Não Apagar'!$C$8,'Não Apagar'!$C$9) -> Segunda-feira | I38: =((H38-E38)-(G38-F38))*24 -> 0 | J38: =MAX(0,MIN(I38,'Não Apagar'!$J$3)) -> 0 | K38: =MAX(0,I38-'Não Apagar'!$J$3) -> 0 | L38: =L37+K38 -> 0 | P38: 1
A39: 1 | C39: =C38+1 -> 45835 | D39: =CHOOSE(WEEKDAY(C39,2),'Não Apagar'!$C$3,'Não Apagar'!$C$4,'Não Apagar'!$C$5,'Não Apagar'!$C$6,'Não Apagar'!$C$7,'Não Apagar'!$C$8,'Não Apagar'!$C$9) -> Sexta-feira | I39: =((H39-E39)-(G39-F39))*24 -> 0 | J39: =MAX(0,MIN(I39,'Não Apagar'!$J$3)) -> 0 | K39: =MAX(0,I39-'Não Apagar'!$J$3) -> 0 | L39: =L38+K39 -> 0 | P39: 1
A40: 1 | C40: =C39+1 -> 45836 | D40: =CHOOSE(WEEKDAY(C40,2),'Não Apagar'!$C$3,'Não Apagar'!$C$4,'Não Apagar'!$C$5,'Não Apagar'!$C$6,'Não Apagar'!$C$7,'Não Apagar'!$C$8,'Não Apagar'!$C$9) -> Sábado | P40: 1
A41: 1 | C41: =C40+1 -> 45837 | D41: =CHOOSE(WEEKDAY(C41,2),'Não Apagar'!$C$3,'Não Apagar'!$C$4,'Não Apagar'!$C$5,'Não Apagar'!$C$6,'Não Apagar'!$C$7,'Não Apagar'!$C$8,'Não Apagar'!$C$9) -> Domingo | P41: 1
...

Sheet Jul.25
A1: 1 | B1: 1 | C1: 1 | D1: 1 | E1: 1 | F1: 1 | G1: 1 | H1: 1 | I1: 1 | J1: 1 | K1: 1 | L1: 1 | M1: 1 | N1: 1 | O1: 1 | P1: 1
C3: Bluzz Saúde Ltda.
A4: 1 | C4: CNPJ | D4: 54.557.861/0001-02 | P4: 1
A5: 1 | C5: Colaborador | P5: 1
A6: 1 | C6: Mês Competência | D6: Jul.25 | P6: 1
A7: 1 | P7: 1
A8: 1 | P8: 1
A9: 1 | P9: 1
A10: 1 | P10: 1
A11: 1 | C11: CONTROLE DE PONTO | P11: 1
A12: 1 | C12: Data | D12: Dia da semana | E12: Entrada | F12: Saída Almoço | G12: Retorno Almoço | H12: Saída | I12: Horas Trabalhadas | J12: Horas Normais | K12: Horas Extras | L12: Banco de Horas | P12: 1
A13: 1 | C13: =Jun.25!C42 -> 45838 | D13: =Jun.25!D42 -> Segunda-feira | P13: 1
A14: 1 | C14: 45839 | D14: =CHOOSE(WEEKDAY(C14,2),'Não Apagar'!$C$3,'Não Apagar'!$C$4,'Não Apagar'!$C$5,'Não Apagar'!$C$6,'Não Apagar'!$C$7,'Não Apagar'!$C$8,'Não Apagar'!$C$9) -> Terça-feira | I14: =((H14-E14)-(G14-F14))*24 -> 0 | J14: =MAX(0,MIN(I14,'Não Apagar'!$J$3)) -> 0 | K14: =MAX(0,I14-'Não Apagar'!$J$3) -> 0 | L14: =K14+Jun.25!L45 -> 0 | P14: 1
